Workbook
Name AffAttrition: Inputs!$B$10
Name SampleAffConv: Inputs!$B$7

Sheet Inputs
A1: LOYALTY PROGRAM FINANCIAL MODEL - INPUTS DASHBOARD
A3: ACQUISITION INPUTS
A4: Parameter | B4: Value | C4: Unit | D4: Name | E4: Description | G4: Used by
A5: Samples Sent - Month 1 | B5: 150 | C5: samples | E5: Initial month sample distribution | G5: Affiliate Projection | Cell B4
A6: Samples Sent - Month 2+ | B6: 100 | C6: samples | E6: Ongoing monthly sample distribution | G6: Affiliate Projection | Row 4
A7: Sample-to-Affiliate Conversion Rate | B7: 0.7 | C7: % | D7: SampleAffConv | E7: Percentage of samples that convert to affiliates | G7: Affiliate Projection | Row 5
A9: PERFORMANCE INPUTS
A10: Parameter | B10: Value | C10: Unit | E10: Description
A11: Gross AOV | B11: 100 | C11: $ | E11: Average order value before discounts | G11: Revenue | Row 5 & Missions | Col J
A12: Rolling Window Duration | B12: 30 | C12: days | E12: Time period for VIP level qualification | G12: Placeholder..
A14: REDEMPTION & BEHAVIOR INPUTS
A15: Parameter | B15: Value | C15: Unit | E15: Description
A16: Discount Redemption Rate | B16: 0.3 | C16: % | E16: Percentage of discount coupons redeemed | G16: Revenue | Row 8
A17: Default Mission Completion Rate | B17: 0.25 | C17: % | E17: Default completion rate for missions | G17: Overriden by mission sheet… delete?
A19: COST INPUTS
A20: Parameter | B20: Value | C20: Unit | E20: Description
A21: Cost per Sample | B21: 15 | C21: $ | E21: Cost of each sample sent (product + shipping) | G21: Costs row 22
A23: MONTHLY LEVEL DISTRIBUTION
A24: (% of affiliates at each level per month)
A25: Level | B25: Month 1 | C25: Month 2 | D25: Month 3 | E25: Month 4 | F25: Month 5 | G25: Month 6 | H25: Month 7 | I25: Month 8 | J25: Month 9 | K25: Month 10 | L25: Month 11 | M25: Month 12
A26: Bronze | B26: 0.9 | C26: 0.8 | D26: 0.7 | E26: 0.62 | F26: 0.55 | G26: 0.5 | H26: 0.47 | I26: 0.44 | J26: 0.42 | K26: 0.4 | L26: 0.38 | M26: 0.36
A27: Silver | B27: 0.1 | C27: 0.15 | D27: 0.2 | E27: 0.23 | F27: 0.26 | G27: 0.28 | H27: 0.29 | I27: 0.3 | J27: 0.3 | K27: 0.3 | L27: 0.3 | M27: 0.3
A28: Gold | B28: 0 | C28: 0.05 | D28: 0.08 | E28: 0.1 | F28: 0.12 | G28: 0.14 | H28: 0.15 | I28: 0.16 | J28: 0.17 | K28: 0.18 | L28: 0.19 | M28: 0.2
A29: Platinum | B29: 0 | C29: 0 | D29: 0.02 | E29: 0.05 | F29: 0.07 | G29: 0.08 | H29: 0.09 | I29: 0.1 | J29: 0.11 | K29: 0.12 | L29: 0.13 | M29: 0.14
A30: Diamond | B30: 0 | C30: 0 | D30: 0 | E30: 0 | F30: 0 | G30: 0 | H30: 0 | I30: 0 | J30: 0 | K30: 0 | L30: 0 | M30: 0
A31: Total (must = 100%) | B31: =SUM(B26:B30) | C31: =SUM(C26:C30) | D31: =SUM(D26:D30) | E31: =SUM(E26:E30) | F31: =SUM(F26:F30) | G31: =SUM(G26:G30) | H31: =SUM(H26:H30) | I31: =SUM(I26:I30) | ... M31: =SUM(M26:M30)
A33: MONTHLY FLYWHEEL AFFILIATES
A34: (Organic inbound affiliates per month)
A35: Flywheel | B35: Month 1 | C35: Month 2 | D35: Month 3 | E35: Month 4 | F35: Month 5 | G35: Month 6 | H35: Month 7 | I35: Month 8 | J35: Month 9 | K35: Month 10 | L35: Month 11 | M35: Month 12
A36: Affiliates | B36: 5 | C36: 8 | D36: 10 | E36: 12 | F36: 15 | G36: 18 | H36: 20 | I36: 22 | J36: 25 | K36: 28 | L36: 30 | M36: 35

Sheet VIP Levels
A1: VIP LEVEL CONFIGURATION
A3: LEVEL THRESHOLDS & COMMISSION
A4: Level # | B4: Name | C4: Sales Threshold | D4: Base Commission % | E4: Avg Sales/Month
A5: 1 | B5: Bronze | C5: 0 | D5: 0.2 | E5: 2
A6: 2 | B6: Silver | C6: 15 | D6: 0.2 | E6: 6
A7: 3 | B7: Gold | C7: 75 | D7: 0.2 | E7: 12
A8: 4 | B8: Platinum | C8: 150 | D8: 0.2 | E8: 25
A9: 5 | B9: Diamond | C9: 0 | D9: 0 | E9: 0
A12: WELCOME REWARDS (Per Level)
A13: Level | B13: Comm Boost Qty | C13: Comm Boost % | D13: Comm Boost Days | E13: Gift Card Qty | F13: Gift Card $ | G13: Discount Qty | H13: Discount % | I13: Discount Days | J13: Spark Ads Qty | K13: Spark Ads $ | L13: Phys Gift Qty | M13: Phys Gift $ | N13: Experience Qty | O13: Experience $
A14: Bronze | B14: 0 | C14: 0.1 | D14: 0 | E14: 0 | F14: 0 | G14: 1 | H14: 0.15 | I14: 7 | J14: 0 | K14: 0 | L14: 0 | M14: 0 | N14: 0 | O14: 0
A15: Silver | B15: 1 | C15: 0.1 | D15: 4 | E15: 1 | F15: 50 | G15: 1 | H15: 0.15 | I15: 7 | J15: 0 | K15: 0 | L15: 0 | M15: 0 | N15: 0 | O15: 0
A16: Gold | B16: 1 | C16: 0.2 | D16: 7 | E16: 1 | F16: 100 | G16: 1 | H16: 0.2 | I16: 7 | J16: 0 | K16: 0 | L16: 0 | M16: 0 | N16: 0 | O16: 0
A17: Platinum | B17: 2 | C17: 0.25 | D17: 7 | E17: 2 | F17: 150 | G17: 1 | H17: 0.2 | I17: 7 | J17: 0 | K17: 0 | L17: 0 | M17: 0 | N17: 0 | O17: 0
A18: Diamond | B18: 0 | C18: 0 | D18: 0 | E18: 0 | F18: 0 | G18: 0 | H18: 0 | I18: 0 | J18: 0 | K18: 0 | L18: 0 | M18: 0 | N18: 0 | O18: 0

Sheet Missions
A1: MISSION CONFIGURATION
A3: MISSIONS BY VIP LEVEL
A4: VIP Level | B4: Mission Type | C4: Target | D4: Repeatability | E4: Completion Rate | F4: Reward Type | G4: Reward Value | H4: Reward Duration | I4: Active? | J4: Cost per Completion
A5: Bronze | B5: Sales | C5: 10 | D5: One-time | E5: 0.5 | F5: Gift Card | G5: 25 | H5: 0 | I5: Yes | J5: =IF(D5="Weekly",(Inputs!$B$12/30)*4,IF(D5="Monthly",Inputs!$B$12/30,1))*IF(F5="Gift Card",G5,IF(F5="Spark Ads",G5,IF(F5="Commission Boost",G5*(INDEX('VIP Levels'!$E$5:$E$9,MATCH(A5,'VIP Levels'!$B$5:$B$9,0))/30*H5)*Revenue!$B$10,IF(F5="Discount",G5*(INDEX('VIP Levels'!$E$5:$E$9,MATCH(A5,'VIP Levels'!$B$5:$B$9,0))/30*H5)*Inputs!$B$11*Inputs!$B$16,0))))
A6: Bronze | B6: Videos | C6: 5 | D6: One-time | E6: 0.8 | F6: Gift Card | G6: 25 | H6: 0 | I6: Yes | J6: =IF(D6="Weekly",(Inputs!$B$12/30)*4,IF(D6="Monthly",Inputs!$B$12/30,1))*IF(F6="Gift Card",G6,IF(F6="Spark Ads",G6,IF(F6="Commission Boost",G6*(INDEX('VIP Levels'!$E$5:$E$9,MATCH(A6,'VIP Levels'!$B$5:$B$9,0))/30*H6)*Revenue!$B$10,IF(F6="Discount",G6*(INDEX('VIP Levels'!$E$5:$E$9,MATCH(A6,'VIP Levels'!$B$5:$B$9,0))/30*H6)*Inputs!$B$11*Inputs!$B$16,0))))
A7: Bronze | B7: Views | C7: 2000 | D7: One-time | E7: 0.9 | F7: Discount | G7: 0.15 | H7: 0 | I7: Yes | J7: =IF(D7="Weekly",(Inputs!$B$12/30)*4,IF(D7="Monthly",Inputs!$B$12/30,1))*IF(F7="Gift Card",G7,IF(F7="Spark Ads",G7,IF(F7="Commission Boost",G7*(INDEX('VIP Levels'!$E$5:$E$9,MATCH(A7,'VIP Levels'!$B$5:$B$9,0))/30*H7)*Revenue!$B$10,IF(F7="Discount",G7*(INDEX('VIP Levels'!$E$5:$E$9,MATCH(A7,'VIP Levels'!$B$5:$B$9,0))/30*H7)*Inputs!$B$11*Inputs!$B$16,0))))
A8: Silver | B8: Sales | C8: 15 | D8: Monthly | E8: 0.6 | F8: Gift Card | G8: 50 | H8: 0 | I8: Yes | J8: =IF(D8="Weekly",(Inputs!$B$12/30)*4,IF(D8="Monthly",Inputs!$B$12/30,1))*IF(F8="Gift Card",G8,IF(F8="Spark Ads",G8,IF(F8="Commission Boost",G8*(INDEX('VIP Levels'!$E$5:$E$9,MATCH(A8,'VIP Levels'!$B$5:$B$9,0))/30*H8)*Revenue!$B$10,IF(F8="Discount",G8*(INDEX('VIP Levels'!$E$5:$E$9,MATCH(A8,'VIP Levels'!$B$5:$B$9,0))/30*H8)*Inputs!$B$11*Inputs!$B$16,0))))
A9: Silver | B9: Videos | C9: 15 | D9: Monthly | E9: 0.6 | F9: Commission Boost | G9: 0.1 | H9: 7 | I9: Yes | J9: =IF(D9="Weekly",(Inputs!$B$12/30)*4,IF(D9="Monthly",Inputs!$B$12/30,1))*IF(F9="Gift Card",G9,IF(F9="Spark Ads",G9,IF(F9="Commission Boost",G9*(INDEX('VIP Levels'!$E$5:$E$9,MATCH(A9,'VIP Levels'!$B$5:$B$9,0))/30*H9)*Revenue!$B$10,IF(F9="Discount",G9*(INDEX('VIP Levels'!$E$5:$E$9,MATCH(A9,'VIP Levels'!$B$5:$B$9,0))/30*H9)*Inputs!$B$11*Inputs!$B$16,0))))
A10: Silver | B10: Views | C10: 10000 | D10: Monthly | E10: 0.8 | F10: Discount | G10: 0.1 | H10: 2 | I10: Yes | J10: =IF(D10="Weekly",(Inputs!$B$12/30)*4,IF(D10="Monthly",Inputs!$B$12/30,1))*IF(F10="Gift Card",G10,IF(F10="Spark Ads",G10,IF(F10="Commission Boost",G10*(INDEX('VIP Levels'!$E$5:$E$9,MATCH(A10,'VIP Levels'!$B$5:$B$9,0))/30*H10)*Revenue!$B$10,IF(F10="Discount",G10*(INDEX('VIP Levels'!$E$5:$E$9,MATCH(A10,'VIP Levels'!$B$5:$B$9,0))/30*H10)*Inputs!$B$11*Inputs!$B$16,0))))
A11: Gold | B11: Sales | C11: 40 | D11: Monthly | E11: 0.5 | F11: Gift Card | G11: 150 | H11: 0 | I11: Yes | J11: =IF(D11="Weekly",(Inputs!$B$12/30)*4,IF(D11="Monthly",Inputs!$B$12/30,1))*IF(F11="Gift Card",G11,IF(F11="Spark Ads",G11,IF(F11="Commission Boost",G11*(INDEX('VIP Levels'!$E$5:$E$9,MATCH(A11,'VIP Levels'!$B$5:$B$9,0))/30*H11)*Revenue!$B$10,IF(F11="Discount",G11*(INDEX('VIP Levels'!$E$5:$E$9,MATCH(A11,'VIP Levels'!$B$5:$B$9,0))/30*H11)*Inputs!$B$11*Inputs!$B$16,0))))
A12: Gold | B12: Views | C12: 20000 | D12: Weekly | E12: 0.7 | F12: Discount | G12: 0.1 | H12: 2 | I12: Yes | J12: =IF(D12="Weekly",(Inputs!$B$12/30)*4,IF(D12="Monthly",Inputs!$B$12/30,1))*IF(F12="Gift Card",G12,IF(F12="Spark Ads",G12,IF(F12="Commission Boost",G12*(INDEX('VIP Levels'!$E$5:$E$9,MATCH(A12,'VIP Levels'!$B$5:$B$9,0))/30*H12)*Revenue!$B$10,IF(F12="Discount",G12*(INDEX('VIP Levels'!$E$5:$E$9,MATCH(A12,'VIP Levels'!$B$5:$B$9,0))/30*H12)*Inputs!$B$11*Inputs!$B$16,0))))
A13: Gold | B13: Videos | C13: 20 | D13: Monthly | E13: 0.7 | F13: Commission Boost | G13: 0.1 | H13: 7 | I13: Yes | J13: =IF(D13="Weekly",(Inputs!$B$12/30)*4,IF(D13="Monthly",Inputs!$B$12/30,1))*IF(F13="Gift Card",G13,IF(F13="Spark Ads",G13,IF(F13="Commission Boost",G13*(INDEX('VIP Levels'!$E$5:$E$9,MATCH(A13,'VIP Levels'!$B$5:$B$9,0))/30*H13)*Revenue!$B$10,IF(F13="Discount",G13*(INDEX('VIP Levels'!$E$5:$E$9,MATCH(A13,'VIP Levels'!$B$5:$B$9,0))/30*H13)*Inputs!$B$11*Inputs!$B$16,0))))
A14: Platinum | B14: Sales | C14: 100 | D14: Monthly | E14: 0.4 | F14: Gift Card | G14: 400 | H14: 0 | I14: Yes | J14: =IF(D14="Weekly",(Inputs!$B$12/30)*4,IF(D14="Monthly",Inputs!$B$12/30,1))*IF(F14="Gift Card",G14,IF(F14="Spark Ads",G14,IF(F14="Commission Boost",G14*(INDEX('VIP Levels'!$E$5:$E$9,MATCH(A14,'VIP Levels'!$B$5:$B$9,0))/30*H14)*Revenue!$B$10,IF(F14="Discount",G14*(INDEX('VIP Levels'!$E$5:$E$9,MATCH(A14,'VIP Levels'!$B$5:$B$9,0))/30*H14)*Inputs!$B$11*Inputs!$B$16,0))))
A15: Platinum | B15: Videos | C15: 10 | D15: Weekly | E15: 0.7 | F15: Commission Boost | G15: 0.15 | H15: 7 | I15: Yes | J15: =IF(D15="Weekly",(Inputs!$B$12/30)*4,IF(D15="Monthly",Inputs!$B$12/30,1))*IF(F15="Gift Card",G15,IF(F15="Spark Ads",G15,IF(F15="Commission Boost",G15*(INDEX('VIP Levels'!$E$5:$E$9,MATCH(A15,'VIP Levels'!$B$5:$B$9,0))/30*H15)*Revenue!$B$10,IF(F15="Discount",G15*(INDEX('VIP Levels'!$E$5:$E$9,MATCH(A15,'VIP Levels'!$B$5:$B$9,0))/30*H15)*Inputs!$B$11*Inputs!$B$16,0))))
A16: Platinum | B16: Views | C16: 20000 | D16: Weekly | E16: 0.5 | F16: Discount | G16: 0.15 | H16: 2 | I16: Yes | J16: =IF(D16="Weekly",(Inputs!$B$12/30)*4,IF(D16="Monthly",Inputs!$B$12/30,1))*IF(F16="Gift Card",G16,IF(F16="Spark Ads",G16,IF(F16="Commission Boost",G16*(INDEX('VIP Levels'!$E$5:$E$9,MATCH(A16,'VIP Levels'!$B$5:$B$9,0))/30*H16)*Revenue!$B$10,IF(F16="Discount",G16*(INDEX('VIP Levels'!$E$5:$E$9,MATCH(A16,'VIP Levels'!$B$5:$B$9,0))/30*H16)*Inputs!$B$11*Inputs!$B$16,0))))
J17: =IF(F17="Gift Card",G17,IF(F17="Spark Ads",G17,IF(F17="Commission Boost",G17*(INDEX('VIP Levels'!$E$5:$E$9,MATCH(A17,'VIP Levels'!$B$5:$B$9,0))/30*H17)*Revenue!$B$10,IF(F17="Discount",G17*(INDEX('VIP Levels'!$E$5:$E$9,MATCH(A17,'VIP Levels'!$B$5:$B$9,0))/30*H17)*Inputs!$B$12*Inputs!$B$16,0))))
J18: =IF(F18="Gift Card",G18,IF(F18="Spark Ads",G18,IF(F18="Commission Boost",G18*(INDEX('VIP Levels'!$E$5:$E$9,MATCH(A18,'VIP Levels'!$B$5:$B$9,0))/30*H18)*Revenue!$B$10,IF(F18="Discount",G18*(INDEX('VIP Levels'!$E$5:$E$9,MATCH(A18,'VIP Levels'!$B$5:$B$9,0))/30*H18)*Inputs!$B$12*Inputs!$B$16,0))))
J19: =IF(F19="Gift Card",G19,IF(F19="Spark Ads",G19,IF(F19="Commission Boost",G19*(INDEX('VIP Levels'!$E$5:$E$9,MATCH(A19,'VIP Levels'!$B$5:$B$9,0))/30*H19)*Revenue!$B$10,IF(F19="Discount",G19*(INDEX('VIP Levels'!$E$5:$E$9,MATCH(A19,'VIP Levels'!$B$5:$B$9,0))/30*H19)*Inputs!$B$12*Inputs!$B$16,0))))
J20: =IF(F20="Gift Card",G20,IF(F20="Spark Ads",G20,IF(F20="Commission Boost",G20*(INDEX('VIP Levels'!$E$5:$E$9,MATCH(A20,'VIP Levels'!$B$5:$B$9,0))/30*H20)*Revenue!$B$10,IF(F20="Discount",G20*(INDEX('VIP Levels'!$E$5:$E$9,MATCH(A20,'VIP Levels'!$B$5:$B$9,0))/30*H20)*Inputs!$B$12*Inputs!$B$16,0))))
J21: =IF(F21="Gift Card",G21,IF(F21="Spark Ads",G21,IF(F21="Commission Boost",G21*(INDEX('VIP Levels'!$E$5:$E$9,MATCH(A21,'VIP Levels'!$B$5:$B$9,0))/30*H21)*Revenue!$B$10,IF(F21="Discount",G21*(INDEX('VIP Levels'!$E$5:$E$9,MATCH(A21,'VIP Levels'!$B$5:$B$9,0))/30*H21)*Inputs!$B$12*Inputs!$B$16,0))))
J22: =IF(F22="Gift Card",G22,IF(F22="Spark Ads",G22,IF(F22="Commission Boost",G22*(INDEX('VIP Levels'!$E$5:$E$9,MATCH(A22,'VIP Levels'!$B$5:$B$9,0))/30*H22)*Revenue!$B$10,IF(F22="Discount",G22*(INDEX('VIP Levels'!$E$5:$E$9,MATCH(A22,'VIP Levels'!$B$5:$B$9,0))/30*H22)*Inputs!$B$12*Inputs!$B$16,0))))
J23: =IF(F23="Gift Card",G23,IF(F23="Spark Ads",G23,IF(F23="Commission Boost",G23*(INDEX('VIP Levels'!$E$5:$E$9,MATCH(A23,'VIP Levels'!$B$5:$B$9,0))/30*H23)*Revenue!$B$10,IF(F23="Discount",G23*(INDEX('VIP Levels'!$E$5:$E$9,MATCH(A23,'VIP Levels'!$B$5:$B$9,0))/30*H23)*Inputs!$B$12*Inputs!$B$16,0))))
J24: =IF(F24="Gift Card",G24,IF(F24="Spark Ads",G24,IF(F24="Commission Boost",G24*(INDEX('VIP Levels'!$E$5:$E$9,MATCH(A24,'VIP Levels'!$B$5:$B$9,0))/30*H24)*Revenue!$B$10,IF(F24="Discount",G24*(INDEX('VIP Levels'!$E$5:$E$9,MATCH(A24,'VIP Levels'!$B$5:$B$9,0))/30*H24)*Inputs!$B$12*Inputs!$B$16,0))))
J25: =IF(F25="Gift Card",G25,IF(F25="Spark Ads",G25,IF(F25="Commission Boost",G25*INDEX('VIP Levels'!$E$5:$E$9,MATCH(A25,'VIP Levels'!$B$5:$B$9,0))*Revenue!$B$10,0)))
J26: =IF(F26="Gift Card",G26,IF(F26="Spark Ads",G26,IF(F26="Commission Boost",G26*INDEX('VIP Levels'!$E$5:$E$9,MATCH(A26,'VIP Levels'!$B$5:$B$9,0))*Revenue!$B$10,0)))
A29: MISSION SUMMARY BY LEVEL
A30: Level | B30: Active Missions | C30: Avg Completion Rate
A31: Bronze | B31: =COUNTIFS(A$6:A$26,A31,I$6:I$26,"Yes") | C31: =IFERROR(AVERAGEIFS(E$6:E$26,A$6:A$26,A31,I$6:I$26,"Yes"),0)
A32: Silver | B32: =COUNTIFS(A$6:A$26,A32,I$6:I$26,"Yes") | C32: =IFERROR(AVERAGEIFS(E$6:E$26,A$6:A$26,A32,I$6:I$26,"Yes"),0)
A33: Gold | B33: =COUNTIFS(A$6:A$26,A33,I$6:I$26,"Yes") | C33: =IFERROR(AVERAGEIFS(E$6:E$26,A$6:A$26,A33,I$6:I$26,"Yes"),0)
A34: Platinum | B34: =COUNTIFS(A$6:A$26,A34,I$6:I$26,"Yes") | C34: =IFERROR(AVERAGEIFS(E$6:E$26,A$6:A$26,A34,I$6:I$26,"Yes"),0)
A35: Diamond | B35: =COUNTIFS(A$6:A$26,A35,I$6:I$26,"Yes") | C35: =IFERROR(AVERAGEIFS(E$6:E$26,A$6:A$26,A35,I$6:I$26,"Yes"),0)
A39: Mission Types: Videos, Likes, Sales, Views
A40: Repeatability: One-time, Weekly, Monthly
A41: Reward Types: Gift Card, Commission Boost, Spark Ads

Sheet Affiliate Projection
A1: AFFILIATE PROJECTION (12 MONTHS)
A3: Metric | B3: Month 1 | C3: Month 2 | D3: Month 3 | E3: Month 4 | F3: Month 5 | G3: Month 6 | H3: Month 7 | I3: Month 8 | J3: Month 9 | K3: Month 10 | L3: Month 11 | M3: Month 12
A4: Samples Sent | B4: =Inputs!$B$5 | C4: =Inputs!$B$6 | D4: =Inputs!$B$6 | E4: =Inputs!$B$6 | F4: =Inputs!$B$6 | G4: =Inputs!$B$6 | H4: =Inputs!$B$6 | I4: =Inputs!$B$6 | J4: =Inputs!$B$6 | ... M4: =Inputs!$B$6
A5: New Affiliates (from Samples) | B5: {=ROUND(B4*SampleAffConv,0)} | C5: =ROUND(C4*SampleAffConv,0) | D5: =ROUND(D4*SampleAffConv,0) | E5: =ROUND(E4*SampleAffConv,0) | F5: =ROUND(F4*SampleAffConv,0) | G5: =ROUND(G4*SampleAffConv,0) | H5: =ROUND(H4*SampleAffConv,0) | I5: =ROUND(I4*SampleAffConv,0) | J5: =ROUND(J4*SampleAffConv,0) | ... M5: =ROUND(M4*SampleAffConv,0)
A6: Flywheel Affiliates | B6: =Inputs!B$36 | C6: =Inputs!C$36 | D6: =Inputs!D$36 | E6: =Inputs!E$36 | F6: =Inputs!F$36 | G6: =Inputs!G$36 | H6: =Inputs!H$36 | I6: =Inputs!I$36 | ... M6: =Inputs!M$36
A7: Total New Affiliates | B7: =B5+B6 | C7: =C5+C6 | D7: =D5+D6 | E7: =E5+E6 | F7: =F5+F6 | G7: =G5+G6 | H7: =H5+H6 | I7: =I5+I6 | ... M7: =M5+M6 | Q7: s
A8: Active Affiliates (End of Month) | B8: =B7 | C8: =B8+C7 | D8: =C8+D7 | E8: =D8+E7 | F8: =E8+F7 | G8: =F8+G7 | H8: =G8+H7 | I8: =H8+I7 | J8: =I8+J7 | ... M8: =L8+M7
A9: Total Sales | B9: =ROUND(B11*'VIP Levels'!$E$5+B12*'VIP Levels'!$E$6+B13*'VIP Levels'!$E$7+B14*'VIP Levels'!$E$8+B15*'VIP Levels'!$E$9,0) | C9: =ROUND(C11*'VIP Levels'!$E$5+C12*'VIP Levels'!$E$6+C13*'VIP Levels'!$E$7+C14*'VIP Levels'!$E$8+C15*'VIP Levels'!$E$9,0) | D9: =ROUND(D11*'VIP Levels'!$E$5+D12*'VIP Levels'!$E$6+D13*'VIP Levels'!$E$7+D14*'VIP Levels'!$E$8+D15*'VIP Levels'!$E$9,0) | E9: =ROUND(E11*'VIP Levels'!$E$5+E12*'VIP Levels'!$E$6+E13*'VIP Levels'!$E$7+E14*'VIP Levels'!$E$8+E15*'VIP Levels'!$E$9,0) | F9: =ROUND(F11*'VIP Levels'!$E$5+F12*'VIP Levels'!$E$6+F13*'VIP Levels'!$E$7+F14*'VIP Levels'!$E$8+F15*'VIP Levels'!$E$9,0) | G9: =ROUND(G11*'VIP Levels'!$E$5+G12*'VIP Levels'!$E$6+G13*'VIP Levels'!$E$7+G14*'VIP Levels'!$E$8+G15*'VIP Levels'!$E$9,0) | H9: =ROUND(H11*'VIP Levels'!$E$5+H12*'VIP Levels'!$E$6+H13*'VIP Levels'!$E$7+H14*'VIP Levels'!$E$8+H15*'VIP Levels'!$E$9,0) | I9: =ROUND(I11*'VIP Levels'!$E$5+I12*'VIP Levels'!$E$6+I13*'VIP Levels'!$E$7+I14*'VIP Levels'!$E$8+I15*'VIP Levels'!$E$9,0) | ... M9: =ROUND(M11*'VIP Levels'!$E$5+M12*'VIP Levels'!$E$6+M13*'VIP Levels'!$E$7+M14*'VIP Levels'!$E$8+M15*'VIP Levels'!$E$9,0)
A10: --- Level Distribution ---
A11: Affiliates at Bronze | B11: =ROUND(B8*Inputs!B$26,0) | C11: =ROUND(C8*Inputs!C$26,0) | D11: =ROUND(D8*Inputs!D$26,0) | E11: =ROUND(E8*Inputs!E$26,0) | F11: =ROUND(F8*Inputs!F$26,0) | G11: =ROUND(G8*Inputs!G$26,0) | H11: =ROUND(H8*Inputs!H$26,0) | I11: =ROUND(I8*Inputs!I$26,0) | ... M11: =ROUND(M8*Inputs!M$26,0)
A12: Affiliates at Silver | B12: =ROUND(B8*Inputs!B$27,0) | C12: =ROUND(C8*Inputs!C$27,0) | D12: =ROUND(D8*Inputs!D$27,0) | E12: =ROUND(E8*Inputs!E$27,0) | F12: =ROUND(F8*Inputs!F$27,0) | G12: =ROUND(G8*Inputs!G$27,0) | H12: =ROUND(H8*Inputs!H$27,0) | I12: =ROUND(I8*Inputs!I$27,0) | ... M12: =ROUND(M8*Inputs!M$27,0)
A13: Affiliates at Gold | B13: =ROUND(B8*Inputs!B$28,0) | C13: =ROUND(C8*Inputs!C$28,0) | D13: =ROUND(D8*Inputs!D$28,0) | E13: =ROUND(E8*Inputs!E$28,0) | F13: =ROUND(F8*Inputs!F$28,0) | G13: =ROUND(G8*Inputs!G$28,0) | H13: =ROUND(H8*Inputs!H$28,0) | I13: =ROUND(I8*Inputs!I$28,0) | ... M13: =ROUND(M8*Inputs!M$28,0)
A14: Affiliates at Platinum | B14: =ROUND(B8*Inputs!B$29,0) | C14: =ROUND(C8*Inputs!C$29,0) | D14: =ROUND(D8*Inputs!D$29,0) | E14: =ROUND(E8*Inputs!E$29,0) | F14: =ROUND(F8*Inputs!F$29,0) | G14: =ROUND(G8*Inputs!G$29,0) | H14: =ROUND(H8*Inputs!H$29,0) | I14: =ROUND(I8*Inputs!I$29,0) | ... M14: =ROUND(M8*Inputs!M$29,0)
A15: Affiliates at Diamond | B15: =ROUND(B8*Inputs!B$30,0) | C15: =ROUND(C8*Inputs!C$30,0) | D15: =ROUND(D8*Inputs!D$30,0) | E15: =ROUND(E8*Inputs!E$30,0) | F15: =ROUND(F8*Inputs!F$30,0) | G15: =ROUND(G8*Inputs!G$30,0) | H15: =ROUND(H8*Inputs!H$30,0) | I15: =ROUND(I8*Inputs!I$30,0) | ... M15: =ROUND(M8*Inputs!M$30,0)
A16: --- Level Events ---
A17: New Affiliate Level-Ups (to Bronze) | B17: =B7 | C17: =C7 | D17: =D7 | E17: =E7 | F17: =F7 | G17: =G7 | H17: =H7 | I17: =I7 | ... M17: =M7
A18: Promotion Events (Bronze to higher) | B18: 0 | C18: =MAX(0,(C12+C13+C14+C15)-(B12+B13+B14+B15)) | D18: =MAX(0,(D12+D13+D14+D15)-(C12+C13+C14+C15)) | E18: =MAX(0,(E12+E13+E14+E15)-(D12+D13+D14+D15)) | F18: =MAX(0,(F12+F13+F14+F15)-(E12+E13+E14+E15)) | G18: =MAX(0,(G12+G13+G14+G15)-(F12+F13+F14+F15)) | H18: =MAX(0,(H12+H13+H14+H15)-(G12+G13+G14+G15)) | I18: =MAX(0,(I12+I13+I14+I15)-(H12+H13+H14+H15)) | J18: =MAX(0,(J12+J13+J14+J15)-(I12+I13+I14+I15)) | ... M18: =MAX(0,(M12+M13+M14+M15)-(L12+L13+L14+L15))
A19: --- New Tier Arrivals (for One-time Missions) ---
A20: New Arrivals at Bronze | B20: =B7 | C20: =C7 | D20: =D7 | E20: =E7 | F20: =F7 | G20: =G7 | H20: =H7 | I20: =I7 | ... M20: =M7
A21: New Arrivals at Silver | B21: =B12 | C21: =MAX(0,C12-B12) | D21: =MAX(0,D12-C12) | E21: =MAX(0,E12-D12) | F21: =MAX(0,F12-E12) | G21: =MAX(0,G12-F12) | H21: =MAX(0,H12-G12) | I21: =MAX(0,I12-H12) | J21: =MAX(0,J12-I12) | ... M21: =MAX(0,M12-L12)
A22: New Arrivals at Gold | B22: =B13 | C22: =MAX(0,C13-B13) | D22: =MAX(0,D13-C13) | E22: =MAX(0,E13-D13) | F22: =MAX(0,F13-E13) | G22: =MAX(0,G13-F13) | H22: =MAX(0,H13-G13) | I22: =MAX(0,I13-H13) | J22: =MAX(0,J13-I13) | ... M22: =MAX(0,M13-L13)
A23: New Arrivals at Platinum | B23: =B14 | C23: =MAX(0,C14-B14) | D23: =MAX(0,D14-C14) | E23: =MAX(0,E14-D14) | F23: =MAX(0,F14-E14) | G23: =MAX(0,G14-F14) | H23: =MAX(0,H14-G14) | I23: =MAX(0,I14-H14) | J23: =MAX(0,J14-I14) | ... M23: =MAX(0,M14-L14)
A24: New Arrivals at Diamond | B24: =B15 | C24: =MAX(0,C15-B15) | D24: =MAX(0,D15-C15) | E24: =MAX(0,E15-D15) | F24: =MAX(0,F15-E15) | G24: =MAX(0,G15-F15) | H24: =MAX(0,H15-G15) | I24: =MAX(0,I15-H15) | J24: =MAX(0,J15-I15) | ... M24: =MAX(0,M15-L15)

Sheet Revenue
A1: REVENUE PROJECTION (12 MONTHS)
A3: Metric | B3: Month 1 | C3: Month 2 | D3: Month 3 | E3: Month 4 | F3: Month 5 | G3: Month 6 | H3: Month 7 | I3: Month 8 | J3: Month 9 | K3: Month 10 | L3: Month 11 | M3: Month 12
A4: Total Sales Volume | B4: ='Affiliate Projection'!B9 | C4: ='Affiliate Projection'!C9 | D4: ='Affiliate Projection'!D9 | E4: ='Affiliate Projection'!E9 | F4: ='Affiliate Projection'!F9 | G4: ='Affiliate Projection'!G9 | H4: ='Affiliate Projection'!H9 | I4: ='Affiliate Projection'!I9 | ... M4: ='Affiliate Projection'!M9
A5: Gross AOV | B5: =Inputs!$B$11 | C5: =Inputs!$B$11 | D5: =Inputs!$B$11 | E5: =Inputs!$B$11 | F5: =Inputs!$B$11 | G5: =Inputs!$B$11 | H5: =Inputs!$B$11 | I5: =Inputs!$B$11 | ... M5: =Inputs!$B$11
A6: Gross Revenue | B6: =B4*B5 | C6: =C4*C5 | D6: =D4*D5 | E6: =E4*E5 | F6: =F4*F5 | G6: =G4*G5 | H6: =H4*H5 | I6: =I4*I5 | ... M6: =M4*M5
A7: Avg Discount % (when redeemed) | B7: =SUMPRODUCT('VIP Levels'!$H$14:$H$18,Inputs!B$26:B$30) | C7: =SUMPRODUCT('VIP Levels'!$H$14:$H$18,Inputs!C$26:C$30) | D7: =SUMPRODUCT('VIP Levels'!$H$14:$H$18,Inputs!D$26:D$30) | E7: =SUMPRODUCT('VIP Levels'!$H$14:$H$18,Inputs!E$26:E$30) | F7: =SUMPRODUCT('VIP Levels'!$H$14:$H$18,Inputs!F$26:F$30) | G7: =SUMPRODUCT('VIP Levels'!$H$14:$H$18,Inputs!G$26:G$30) | H7: =SUMPRODUCT('VIP Levels'!$H$14:$H$18,Inputs!H$26:H$30) | I7: =SUMPRODUCT('VIP Levels'!$H$14:$H$18,Inputs!I$26:I$30) | ... M7: =SUMPRODUCT('VIP Levels'!$H$14:$H$18,Inputs!M$26:M$30)
A8: Discount Redemption Rate | B8: =Inputs!$B$16 | C8: =Inputs!$B$16 | D8: =Inputs!$B$16 | E8: =Inputs!$B$16 | F8: =Inputs!$B$16 | G8: =Inputs!$B$16 | H8: =Inputs!$B$16 | I8: =Inputs!$B$16 | ... M8: =Inputs!$B$16
A9: Discounted Sales Count | B9: =ROUND(B4*B8,0) | C9: =ROUND(C4*C8,0) | D9: =ROUND(D4*D8,0) | E9: =ROUND(E4*E8,0) | F9: =ROUND(F4*F8,0) | G9: =ROUND(G4*G8,0) | H9: =ROUND(H4*H8,0) | I9: =ROUND(I4*I8,0) | ... M9: =ROUND(M4*M8,0)
A10: Net AOV (weighted avg) | B10: =B5*(1-B7*B8) | C10: =C5*(1-C7*C8) | D10: =D5*(1-D7*D8) | E10: =E5*(1-E7*E8) | F10: =F5*(1-F7*F8) | G10: =G5*(1-G7*G8) | H10: =H5*(1-H7*H8) | I10: =I5*(1-I7*I8) | ... M10: =M5*(1-M7*M8)
A11: Net Revenue | B11: =B4*B10 | C11: =C4*C10 | D11: =D4*D10 | E11: =E4*E10 | F11: =F4*F10 | G11: =G4*G10 | H11: =H4*H10 | I11: =I4*I10 | ... M11: =M4*M10
A12: Discount Margin Erosion | B12: =B6-B11 | C12: =C6-C11 | D12: =D6-D11 | E12: =E6-E11 | F12: =F6-F11 | G12: =G6-G11 | H12: =H6-H11 | I12: =I6-I11 | ... M12: =M6-M11

Sheet Costs
A1: COST PROJECTION (12 MONTHS)
A3: Metric | B3: Month 1 | C3: Month 2 | D3: Month 3 | E3: Month 4 | F3: Month 5 | G3: Month 6 | H3: Month 7 | I3: Month 8 | J3: Month 9 | K3: Month 10 | L3: Month 11 | M3: Month 12
A4: --- CM1 COSTS (Per Sale) ---
A5: Base Commission Cost | B5: =Revenue!B11*SUMPRODUCT('VIP Levels'!$D$5:$D$9,Inputs!B$26:B$30) | C5: =Revenue!C11*SUMPRODUCT('VIP Levels'!$D$5:$D$9,Inputs!C$26:C$30) | D5: =Revenue!D11*SUMPRODUCT('VIP Levels'!$D$5:$D$9,Inputs!D$26:D$30) | E5: =Revenue!E11*SUMPRODUCT('VIP Levels'!$D$5:$D$9,Inputs!E$26:E$30) | F5: =Revenue!F11*SUMPRODUCT('VIP Levels'!$D$5:$D$9,Inputs!F$26:F$30) | G5: =Revenue!G11*SUMPRODUCT('VIP Levels'!$D$5:$D$9,Inputs!G$26:G$30) | H5: =Revenue!H11*SUMPRODUCT('VIP Levels'!$D$5:$D$9,Inputs!H$26:H$30) | I5: =Revenue!I11*SUMPRODUCT('VIP Levels'!$D$5:$D$9,Inputs!I$26:I$30) | ... M5: =Revenue!M11*SUMPRODUCT('VIP Levels'!$D$5:$D$9,Inputs!M$26:M$30)
A6: Commission Boost Cost (Welcome) | B6: ='Affiliate Projection'!B20*'VIP Levels'!$B$14*'VIP Levels'!$E$5*('VIP Levels'!$D$14/30)*'VIP Levels'!$C$14*Revenue!B10+'Affiliate Projection'!B21*'VIP Levels'!$B$15*'VIP Levels'!$E$6*('VIP Levels'!$D$15/30)*'VIP Levels'!$C$15*Revenue!B10+'Affiliate Projection'!B22*'VIP Levels'!$B$16*'VIP Levels'!$E$7*('VIP Levels'!$D$16/30)*'VIP Levels'!$C$16*Revenue!B10+'Affiliate Projection'!B23*'VIP Levels'!$B$17*'VIP Levels'!$E$8*('VIP Levels'!$D$17/30)*'VIP Levels'!$C$17*Revenue!B10+'Affiliate Projection'!B24*'VIP Levels'!$B$18*'VIP Levels'!$E$9*('VIP Levels'!$D$18/30)*'VIP Levels'!$C$18*Revenue!B10 | C6: ='Affiliate Projection'!C20*'VIP Levels'!$B$14*'VIP Levels'!$E$5*('VIP Levels'!$D$14/30)*'VIP Levels'!$C$14*Revenue!C10+'Affiliate Projection'!C21*'VIP Levels'!$B$15*'VIP Levels'!$E$6*('VIP Levels'!$D$15/30)*'VIP Levels'!$C$15*Revenue!C10+'Affiliate Projection'!C22*'VIP Levels'!$B$16*'VIP Levels'!$E$7*('VIP Levels'!$D$16/30)*'VIP Levels'!$C$16*Revenue!C10+'Affiliate Projection'!C23*'VIP Levels'!$B$17*'VIP Levels'!$E$8*('VIP Levels'!$D$17/30)*'VIP Levels'!$C$17*Revenue!C10+'Affiliate Projection'!C24*'VIP Levels'!$B$18*'VIP Levels'!$E$9*('VIP Levels'!$D$18/30)*'VIP Levels'!$C$18*Revenue!C10 | D6: ='Affiliate Projection'!D20*'VIP Levels'!$B$14*'VIP Levels'!$E$5*('VIP Levels'!$D$14/30)*'VIP Levels'!$C$14*Revenue!D10+'Affiliate Projection'!D21*'VIP Levels'!$B$15*'VIP Levels'!$E$6*('VIP Levels'!$D$15/30)*'VIP Levels'!$C$15*Revenue!D10+'Affiliate Projection'!D22*'VIP Levels'!$B$16*'VIP Levels'!$E$7*('VIP Levels'!$D$16/30)*'VIP Levels'!$C$16*Revenue!D10+'Affiliate Projection'!D23*'VIP Levels'!$B$17*'VIP Levels'!$E$8*('VIP Levels'!$D$17/30)*'VIP Levels'!$C$17*Revenue!D10+'Affiliate Projection'!D24*'VIP Levels'!$B$18*'VIP Levels'!$E$9*('VIP Levels'!$D$18/30)*'VIP Levels'!$C$18*Revenue!D10 | E6: ='Affiliate Projection'!E20*'VIP Levels'!$B$14*'VIP Levels'!$E$5*('VIP Levels'!$D$14/30)*'VIP Levels'!$C$14*Revenue!E10+'Affiliate Projection'!E21*'VIP Levels'!$B$15*'VIP Levels'!$E$6*('VIP Levels'!$D$15/30)*'VIP Levels'!$C$15*Revenue!E10+'Affiliate Projection'!E22*'VIP Levels'!$B$16*'VIP Levels'!$E$7*('VIP Levels'!$D$16/30)*'VIP Levels'!$C$16*Revenue!E10+'Affiliate Projection'!E23*'VIP Levels'!$B$17*'VIP Levels'!$E$8*('VIP Levels'!$D$17/30)*'VIP Levels'!$C$17*Revenue!E10+'Affiliate Projection'!E24*'VIP Levels'!$B$18*'VIP Levels'!$E$9*('VIP Levels'!$D$18/30)*'VIP Levels'!$C$18*Revenue!E10 | F6: ='Affiliate Projection'!F20*'VIP Levels'!$B$14*'VIP Levels'!$E$5*('VIP Levels'!$D$14/30)*'VIP Levels'!$C$14*Revenue!F10+'Affiliate Projection'!F21*'VIP Levels'!$B$15*'VIP Levels'!$E$6*('VIP Levels'!$D$15/30)*'VIP Levels'!$C$15*Revenue!F10+'Affiliate Projection'!F22*'VIP Levels'!$B$16*'VIP Levels'!$E$7*('VIP Levels'!$D$16/30)*'VIP Levels'!$C$16*Revenue!F10+'Affiliate Projection'!F23*'VIP Levels'!$B$17*'VIP Levels'!$E$8*('VIP Levels'!$D$17/30)*'VIP Levels'!$C$17*Revenue!F10+'Affiliate Projection'!F24*'VIP Levels'!$B$18*'VIP Levels'!$E$9*('VIP Levels'!$D$18/30)*'VIP Levels'!$C$18*Revenue!F10 | G6: ='Affiliate Projection'!G20*'VIP Levels'!$B$14*'VIP Levels'!$E$5*('VIP Levels'!$D$14/30)*'VIP Levels'!$C$14*Revenue!G10+'Affiliate Projection'!G21*'VIP Levels'!$B$15*'VIP Levels'!$E$6*('VIP Levels'!$D$15/30)*'VIP Levels'!$C$15*Revenue!G10+'Affiliate Projection'!G22*'VIP Levels'!$B$16*'VIP Levels'!$E$7*('VIP Levels'!$D$16/30)*'VIP Levels'!$C$16*Revenue!G10+'Affiliate Projection'!G23*'VIP Levels'!$B$17*'VIP Levels'!$E$8*('VIP Levels'!$D$17/30)*'VIP Levels'!$C$17*Revenue!G10+'Affiliate Projection'!G24*'VIP Levels'!$B$18*'VIP Levels'!$E$9*('VIP Levels'!$D$18/30)*'VIP Levels'!$C$18*Revenue!G10 | H6: ='Affiliate Projection'!H20*'VIP Levels'!$B$14*'VIP Levels'!$E$5*('VIP Levels'!$D$14/30)*'VIP Levels'!$C$14*Revenue!H10+'Affiliate Projection'!H21*'VIP Levels'!$B$15*'VIP Levels'!$E$6*('VIP Levels'!$D$15/30)*'VIP Levels'!$C$15*Revenue!H10+'Affiliate Projection'!H22*'VIP Levels'!$B$16*'VIP Levels'!$E$7*('VIP Levels'!$D$16/30)*'VIP Levels'!$C$16*Revenue!H10+'Affiliate Projection'!H23*'VIP Levels'!$B$17*'VIP Levels'!$E$8*('VIP Levels'!$D$17/30)*'VIP Levels'!$C$17*Revenue!H10+'Affiliate Projection'!H24*'VIP Levels'!$B$18*'VIP Levels'!$E$9*('VIP Levels'!$D$18/30)*'VIP Levels'!$C$18*Revenue!H10 | I6: ='Affiliate Projection'!I20*'VIP Levels'!$B$14*'VIP Levels'!$E$5*('VIP Levels'!$D$14/30)*'VIP Levels'!$C$14*Revenue!I10+'Affiliate Projection'!I21*'VIP Levels'!$B$15*'VIP Levels'!$E$6*('VIP Levels'!$D$15/30)*'VIP Levels'!$C$15*Revenue!I10+'Affiliate Projection'!I22*'VIP Levels'!$B$16*'VIP Levels'!$E$7*('VIP Levels'!$D$16/30)*'VIP Levels'!$C$16*Revenue!I10+'Affiliate Projection'!I23*'VIP Levels'!$B$17*'VIP Levels'!$E$8*('VIP Levels'!$D$17/30)*'VIP Levels'!$C$17*Revenue!I10+'Affiliate Projection'!I24*'VIP Levels'!$B$18*'VIP Levels'!$E$9*('VIP Levels'!$D$18/30)*'VIP Levels'!$C$18*Revenue!I10 | ... M6: ='Affiliate Projection'!M20*'VIP Levels'!$B$14*'VIP Levels'!$E$5*('VIP Levels'!$D$14/30)*'VIP Levels'!$C$14*Revenue!M10+'Affiliate Projection'!M21*'VIP Levels'!$B$15*'VIP Levels'!$E$6*('VIP Levels'!$D$15/30)*'VIP Levels'!$C$15*Revenue!M10+'Affiliate Projection'!M22*'VIP Levels'!$B$16*'VIP Levels'!$E$7*('VIP Levels'!$D$16/30)*'VIP Levels'!$C$16*Revenue!M10+'Affiliate Projection'!M23*'VIP Levels'!$B$17*'VIP Levels'!$E$8*('VIP Levels'!$D$17/30)*'VIP Levels'!$C$17*Revenue!M10+'Affiliate Projection'!M24*'VIP Levels'!$B$18*'VIP Levels'!$E$9*('VIP Levels'!$D$18/30)*'VIP Levels'!$C$18*Revenue!M10
A7: Commission Boost Cost (Missions) | B7: =SUMPRODUCT((Missions!$F$6:$F$26="Commission Boost")*(Missions!$A$6:$A$26="Bronze")*(Missions!$D$6:$D$26="One-time")*'Affiliate Projection'!B20*Missions!$E$6:$E$26*Missions!$J$6:$J$26)+SUMPRODUCT((Missions!$F$6:$F$26="Commission Boost")*(Missions!$A$6:$A$26="Bronze")*(Missions!$D$6:$D$26<>"One-time")*'Affiliate Projection'!B11*Missions!$E$6:$E$26*Missions!$J$6:$J$26)+SUMPRODUCT((Missions!$F$6:$F$26="Commission Boost")*(Missions!$A$6:$A$26="Silver")*(Missions!$D$6:$D$26="One-time")*'Affiliate Projection'!B21*Missions!$E$6:$E$26*Missions!$J$6:$J$26)+SUMPRODUCT((Missions!$F$6:$F$26="Commission Boost")*(Missions!$A$6:$A$26="Silver")*(Missions!$D$6:$D$26<>"One-time")*'Affiliate Projection'!B12*Missions!$E$6:$E$26*Missions!$J$6:$J$26)+SUMPRODUCT((Missions!$F$6:$F$26="Commission Boost")*(Missions!$A$6:$A$26="Gold")*(Missions!$D$6:$D$26="One-time")*'Affiliate Projection'!B22*Missions!$E$6:$E$26*Missions!$J$6:$J$26)+SUMPRODUCT((Missions!$F$6:$F$26="Commission Boost")*(Missions!$A$6:$A$26="Gold")*(Missions!$D$6:$D$26<>"One-time")*'Affiliate Projection'!B13*Missions!$E$6:$E$26*Missions!$J$6:$J$26)+SUMPRODUCT((Missions!$F$6:$F$26="Commission Boost")*(Missions!$A$6:$A$26="Platinum")*(Missions!$D$6:$D$26="One-time")*'Affiliate Projection'!B23*Missions!$E$6:$E$26*Missions!$J$6:$J$26)+SUMPRODUCT((Missions!$F$6:$F$26="Commission Boost")*(Missions!$A$6:$A$26="Platinum")*(Missions!$D$6:$D$26<>"One-time")*'Affiliate Projection'!B14*Missions!$E$6:$E$26*Missions!$J$6:$J$26)+SUMPRODUCT((Missions!$F$6:$F$26="Commission Boost")*(Missions!$A$6:$A$26="Diamond")*(Missions!$D$6:$D$26="One-time")*'Affiliate Projection'!B24*Missions!$E$6:$E$26*Missions!$J$6:$J$26)+SUMPRODUCT((Missions!$F$6:$F$26="Commission Boost")*(Missions!$A$6:$A$26="Diamond")*(Missions!$D$6:$D$26<>"One-time")*'Affiliate Projection'!B15*Missions!$E$6:$E$26*Missions!$J$6:$J$26) | C7: =SUMPRODUCT((Missions!$F$6:$F$26="Commission Boost")*(Missions!$A$6:$A$26="Bronze")*(Missions!$D$6:$D$26="One-time")*'Affiliate Projection'!C20*Missions!$E$6:$E$26*Missions!$J$6:$J$26)+SUMPRODUCT((Missions!$F$6:$F$26="Commission Boost")*(Missions!$A$6:$A$26="Bronze")*(Missions!$D$6:$D$26<>"One-time")*'Affiliate Projection'!C11*Missions!$E$6:$E$26*Missions!$J$6:$J$26)+SUMPRODUCT((Missions!$F$6:$F$26="Commission Boost")*(Missions!$A$6:$A$26="Silver")*(Missions!$D$6:$D$26="One-time")*'Affiliate Projection'!C21*Missions!$E$6:$E$26*Missions!$J$6:$J$26)+SUMPRODUCT((Missions!$F$6:$F$26="Commission Boost")*(Missions!$A$6:$A$26="Silver")*(Missions!$D$6:$D$26<>"One-time")*'Affiliate Projection'!C12*Missions!$E$6:$E$26*Missions!$J$6:$J$26)+SUMPRODUCT((Missions!$F$6:$F$26="Commission Boost")*(Missions!$A$6:$A$26="Gold")*(Missions!$D$6:$D$26="One-time")*'Affiliate Projection'!C22*Missions!$E$6:$E$26*Missions!$J$6:$J$26)+SUMPRODUCT((Missions!$F$6:$F$26="Commission Boost")*(Missions!$A$6:$A$26="Gold")*(Missions!$D$6:$D$26<>"One-time")*'Affiliate Projection'!C13*Missions!$E$6:$E$26*Missions!$J$6:$J$26)+SUMPRODUCT((Missions!$F$6:$F$26="Commission Boost")*(Missions!$A$6:$A$26="Platinum")*(Missions!$D$6:$D$26="One-time")*'Affiliate Projection'!C23*Missions!$E$6:$E$26*Missions!$J$6:$J$26)+SUMPRODUCT((Missions!$F$6:$F$26="Commission Boost")*(Missions!$A$6:$A$26="Platinum")*(Missions!$D$6:$D$26<>"One-time")*'Affiliate Projection'!C14*Missions!$E$6:$E$26*Missions!$J$6:$J$26)+SUMPRODUCT((Missions!$F$6:$F$26="Commission Boost")*(Missions!$A$6:$A$26="Diamond")*(Missions!$D$6:$D$26="One-time")*'Affiliate Projection'!C24*Missions!$E$6:$E$26*Missions!$J$6:$J$26)+SUMPRODUCT((Missions!$F$6:$F$26="Commission Boost")*(Missions!$A$6:$A$26="Diamond")*(Missions!$D$6:$D$26<>"One-time")*'Affiliate Projection'!C15*Missions!$E$6:$E$26*Missions!$J$6:$J$26) | D7: =SUMPRODUCT((Missions!$F$6:$F$26="Commission Boost")*(Missions!$A$6:$A$26="Bronze")*(Missions!$D$6:$D$26="One-time")*'Affiliate Projection'!D20*Missions!$E$6:$E$26*Missions!$J$6:$J$26)+SUMPRODUCT((Missions!$F$6:$F$26="Commission Boost")*(Missions!$A$6:$A$26="Bronze")*(Missions!$D$6:$D$26<>"One-time")*'Affiliate Projection'!D11*Missions!$E$6:$E$26*Missions!$J$6:$J$26)+SUMPRODUCT((Missions!$F$6:$F$26="Commission Boost")*(Missions!$A$6:$A$26="Silver")*(Missions!$D$6:$D$26="One-time")*'Affiliate Projection'!D21*Missions!$E$6:$E$26*Missions!$J$6:$J$26)+SUMPRODUCT((Missions!$F$6:$F$26="Commission Boost")*(Missions!$A$6:$A$26="Silver")*(Missions!$D$6:$D$26<>"One-time")*'Affiliate Projection'!D12*Missions!$E$6:$E$26*Missions!$J$6:$J$26)+SUMPRODUCT((Missions!$F$6:$F$26="Commission Boost")*(Missions!$A$6:$A$26="Gold")*(Missions!$D$6:$D$26="One-time")*'Affiliate Projection'!D22*Missions!$E$6:$E$26*Missions!$J$6:$J$26)+SUMPRODUCT((Missions!$F$6:$F$26="Commission Boost")*(Missions!$A$6:$A$26="Gold")*(Missions!$D$6:$D$26<>"One-time")*'Affiliate Projection'!D13*Missions!$E$6:$E$26*Missions!$J$6:$J$26)+SUMPRODUCT((Missions!$F$6:$F$26="Commission Boost")*(Missions!$A$6:$A$26="Platinum")*(Missions!$D$6:$D$26="One-time")*'Affiliate Projection'!D23*Missions!$E$6:$E$26*Missions!$J$6:$J$26)+SUMPRODUCT((Missions!$F$6:$F$26="Commission Boost")*(Missions!$A$6:$A$26="Platinum")*(Missions!$D$6:$D$26<>"One-time")*'Affiliate Projection'!D14*Missions!$E$6:$E$26*Missions!$J$6:$J$26)+SUMPRODUCT((Missions!$F$6:$F$26="Commission Boost")*(Missions!$A$6:$A$26="Diamond")*(Missions!$D$6:$D$26="One-time")*'Affiliate Projection'!D24*Missions!$E$6:$E$26*Missions!$J$6:$J$26)+SUMPRODUCT((Missions!$F$6:$F$26="Commission Boost")*(Missions!$A$6:$A$26="Diamond")*(Missions!$D$6:$D$26<>"One-time")*'Affiliate Projection'!D15*Missions!$E$6:$E$26*Missions!$J$6:$J$26) | E7: =SUMPRODUCT((Missions!$F$6:$F$26="Commission Boost")*(Missions!$A$6:$A$26="Bronze")*(Missions!$D$6:$D$26="One-time")*'Affiliate Projection'!E20*Missions!$E$6:$E$26*Missions!$J$6:$J$26)+SUMPRODUCT((Missions!$F$6:$F$26="Commission Boost")*(Missions!$A$6:$A$26="Bronze")*(Missions!$D$6:$D$26<>"One-time")*'Affiliate Projection'!E11*Missions!$E$6:$E$26*Missions!$J$6:$J$26)+SUMPRODUCT((Missions!$F$6:$F$26="Commission Boost")*(Missions!$A$6:$A$26="Silver")*(Missions!$D$6:$D$26="One-time")*'Affiliate Projection'!E21*Missions!$E$6:$E$26*Missions!$J$6:$J$26)+SUMPRODUCT((Missions!$F$6:$F$26="Commission Boost")*(Missions!$A$6:$A$26="Silver")*(Missions!$D$6:$D$26<>"One-time")*'Affiliate Projection'!E12*Missions!$E$6:$E$26*Missions!$J$6:$J$26)+SUMPRODUCT((Missions!$F$6:$F$26="Commission Boost")*(Missions!$A$6:$A$26="Gold")*(Missions!$D$6:$D$26="One-time")*'Affiliate Projection'!E22*Missions!$E$6:$E$26*Missions!$J$6:$J$26)+SUMPRODUCT((Missions!$F$6:$F$26="Commission Boost")*(Missions!$A$6:$A$26="Gold")*(Missions!$D$6:$D$26<>"One-time")*'Affiliate Projection'!E13*Missions!$E$6:$E$26*Missions!$J$6:$J$26)+SUMPRODUCT((Missions!$F$6:$F$26="Commission Boost")*(Missions!$A$6:$A$26="Platinum")*(Missions!$D$6:$D$26="One-time")*'Affiliate Projection'!E23*Missions!$E$6:$E$26*Missions!$J$6:$J$26)+SUMPRODUCT((Missions!$F$6:$F$26="Commission Boost")*(Missions!$A$6:$A$26="Platinum")*(Missions!$D$6:$D$26<>"One-time")*'Affiliate Projection'!E14*Missions!$E$6:$E$26*Missions!$J$6:$J$26)+SUMPRODUCT((Missions!$F$6:$F$26="Commission Boost")*(Missions!$A$6:$A$26="Diamond")*(Missions!$D$6:$D$26="One-time")*'Affiliate Projection'!E24*Missions!$E$6:$E$26*Missions!$J$6:$J$26)+SUMPRODUCT((Missions!$F$6:$F$26="Commission Boost")*(Missions!$A$6:$A$26="Diamond")*(Missions!$D$6:$D$26<>"One-time")*'Affiliate Projection'!E15*Missions!$E$6:$E$26*Missions!$J$6:$J$26) | F7: =SUMPRODUCT((Missions!$F$6:$F$26="Commission Boost")*(Missions!$A$6:$A$26="Bronze")*(Missions!$D$6:$D$26="One-time")*'Affiliate Projection'!F20*Missions!$E$6:$E$26*Missions!$J$6:$J$26)+SUMPRODUCT((Missions!$F$6:$F$26="Commission Boost")*(Missions!$A$6:$A$26="Bronze")*(Missions!$D$6:$D$26<>"One-time")*'Affiliate Projection'!F11*Missions!$E$6:$E$26*Missions!$J$6:$J$26)+SUMPRODUCT((Missions!$F$6:$F$26="Commission Boost")*(Missions!$A$6:$A$26="Silver")*(Missions!$D$6:$D$26="One-time")*'Affiliate Projection'!F21*Missions!$E$6:$E$26*Missions!$J$6:$J$26)+SUMPRODUCT((Missions!$F$6:$F$26="Commission Boost")*(Missions!$A$6:$A$26="Silver")*(Missions!$D$6:$D$26<>"One-time")*'Affiliate Projection'!F12*Missions!$E$6:$E$26*Missions!$J$6:$J$26)+SUMPRODUCT((Missions!$F$6:$F$26="Commission Boost")*(Missions!$A$6:$A$26="Gold")*(Missions!$D$6:$D$26="One-time")*'Affiliate Projection'!F22*Missions!$E$6:$E$26*Missions!$J$6:$J$26)+SUMPRODUCT((Missions!$F$6:$F$26="Commission Boost")*(Missions!$A$6:$A$26="Gold")*(Missions!$D$6:$D$26<>"One-time")*'Affiliate Projection'!F13*Missions!$E$6:$E$26*Missions!$J$6:$J$26)+SUMPRODUCT((Missions!$F$6:$F$26="Commission Boost")*(Missions!$A$6:$A$26="Platinum")*(Missions!$D$6:$D$26="One-time")*'Affiliate Projection'!F23*Missions!$E$6:$E$26*Missions!$J$6:$J$26)+SUMPRODUCT((Missions!$F$6:$F$26="Commission Boost")*(Missions!$A$6:$A$26="Platinum")*(Missions!$D$6:$D$26<>"One-time")*'Affiliate Projection'!F14*Missions!$E$6:$E$26*Missions!$J$6:$J$26)+SUMPRODUCT((Missions!$F$6:$F$26="Commission Boost")*(Missions!$A$6:$A$26="Diamond")*(Missions!$D$6:$D$26="One-time")*'Affiliate Projection'!F24*Missions!$E$6:$E$26*Missions!$J$6:$J$26)+SUMPRODUCT((Missions!$F$6:$F$26="Commission Boost")*(Missions!$A$6:$A$26="Diamond")*(Missions!$D$6:$D$26<>"One-time")*'Affiliate Projection'!F15*Missions!$E$6:$E$26*Missions!$J$6:$J$26) | G7: =SUMPRODUCT((Missions!$F$6:$F$26="Commission Boost")*(Missions!$A$6:$A$26="Bronze")*(Missions!$D$6:$D$26="One-time")*'Affiliate Projection'!G20*Missions!$E$6:$E$26*Missions!$J$6:$J$26)+SUMPRODUCT((Missions!$F$6:$F$26="Commission Boost")*(Missions!$A$6:$A$26="Bronze")*(Missions!$D$6:$D$26<>"One-time")*'Affiliate Projection'!G11*Missions!$E$6:$E$26*Missions!$J$6:$J$26)+SUMPRODUCT((Missions!$F$6:$F$26="Commission Boost")*(Missions!$A$6:$A$26="Silver")*(Missions!$D$6:$D$26="One-time")*'Affiliate Projection'!G21*Missions!$E$6:$E$26*Missions!$J$6:$J$26)+SUMPRODUCT((Missions!$F$6:$F$26="Commission Boost")*(Missions!$A$6:$A$26="Silver")*(Missions!$D$6:$D$26<>"One-time")*'Affiliate Projection'!G12*Missions!$E$6:$E$26*Missions!$J$6:$J$26)+SUMPRODUCT((Missions!$F$6:$F$26="Commission Boost")*(Missions!$A$6:$A$26="Gold")*(Missions!$D$6:$D$26="One-time")*'Affiliate Projection'!G22*Missions!$E$6:$E$26*Missions!$J$6:$J$26)+SUMPRODUCT((Missions!$F$6:$F$26="Commission Boost")*(Missions!$A$6:$A$26="Gold")*(Missions!$D$6:$D$26<>"One-time")*'Affiliate Projection'!G13*Missions!$E$6:$E$26*Missions!$J$6:$J$26)+SUMPRODUCT((Missions!$F$6:$F$26="Commission Boost")*(Missions!$A$6:$A$26="Platinum")*(Missions!$D$6:$D$26="One-time")*'Affiliate Projection'!G23*Missions!$E$6:$E$26*Missions!$J$6:$J$26)+SUMPRODUCT((Missions!$F$6:$F$26="Commission Boost")*(Missions!$A$6:$A$26="Platinum")*(Missions!$D$6:$D$26<>"One-time")*'Affiliate Projection'!G14*Missions!$E$6:$E$26*Missions!$J$6:$J$26)+SUMPRODUCT((Missions!$F$6:$F$26="Commission Boost")*(Missions!$A$6:$A$26="Diamond")*(Missions!$D$6:$D$26="One-time")*'Affiliate Projection'!G24*Missions!$E$6:$E$26*Missions!$J$6:$J$26)+SUMPRODUCT((Missions!$F$6:$F$26="Commission Boost")*(Missions!$A$6:$A$26="Diamond")*(Missions!$D$6:$D$26<>"One-time")*'Affiliate Projection'!G15*Missions!$E$6:$E$26*Missions!$J$6:$J$26) | H7: =SUMPRODUCT((Missions!$F$6:$F$26="Commission Boost")*(Missions!$A$6:$A$26="Bronze")*(Missions!$D$6:$D$26="One-time")*'Affiliate Projection'!H20*Missions!$E$6:$E$26*Missions!$J$6:$J$26)+SUMPRODUCT((Missions!$F$6:$F$26="Commission Boost")*(Missions!$A$6:$A$26="Bronze")*(Missions!$D$6:$D$26<>"One-time")*'Affiliate Projection'!H11*Missions!$E$6:$E$26*Missions!$J$6:$J$26)+SUMPRODUCT((Missions!$F$6:$F$26="Commission Boost")*(Missions!$A$6:$A$26="Silver")*(Missions!$D$6:$D$26="One-time")*'Affiliate Projection'!H21*Missions!$E$6:$E$26*Missions!$J$6:$J$26)+SUMPRODUCT((Missions!$F$6:$F$26="Commission Boost")*(Missions!$A$6:$A$26="Silver")*(Missions!$D$6:$D$26<>"One-time")*'Affiliate Projection'!H12*Missions!$E$6:$E$26*Missions!$J$6:$J$26)+SUMPRODUCT((Missions!$F$6:$F$26="Commission Boost")*(Missions!$A$6:$A$26="Gold")*(Missions!$D$6:$D$26="One-time")*'Affiliate Projection'!H22*Missions!$E$6:$E$26*Missions!$J$6:$J$26)+SUMPRODUCT((Missions!$F$6:$F$26="Commission Boost")*(Missions!$A$6:$A$26="Gold")*(Missions!$D$6:$D$26<>"One-time")*'Affiliate Projection'!H13*Missions!$E$6:$E$26*Missions!$J$6:$J$26)+SUMPRODUCT((Missions!$F$6:$F$26="Commission Boost")*(Missions!$A$6:$A$26="Platinum")*(Missions!$D$6:$D$26="One-time")*'Affiliate Projection'!H23*Missions!$E$6:$E$26*Missions!$J$6:$J$26)+SUMPRODUCT((Missions!$F$6:$F$26="Commission Boost")*(Missions!$A$6:$A$26="Platinum")*(Missions!$D$6:$D$26<>"One-time")*'Affiliate Projection'!H14*Missions!$E$6:$E$26*Missions!$J$6:$J$26)+SUMPRODUCT((Missions!$F$6:$F$26="Commission Boost")*(Missions!$A$6:$A$26="Diamond")*(Missions!$D$6:$D$26="One-time")*'Affiliate Projection'!H24*Missions!$E$6:$E$26*Missions!$J$6:$J$26)+SUMPRODUCT((Missions!$F$6:$F$26="Commission Boost")*(Missions!$A$6:$A$26="Diamond")*(Missions!$D$6:$D$26<>"One-time")*'Affiliate Projection'!H15*Missions!$E$6:$E$26*Missions!$J$6:$J$26) | I7: =SUMPRODUCT((Missions!$F$6:$F$26="Commission Boost")*(Missions!$A$6:$A$26="Bronze")*(Missions!$D$6:$D$26="One-time")*'Affiliate Projection'!I20*Missions!$E$6:$E$26*Missions!$J$6:$J$26)+SUMPRODUCT((Missions!$F$6:$F$26="Commission Boost")*(Missions!$A$6:$A$26="Bronze")*(Missions!$D$6:$D$26<>"One-time")*'Affiliate Projection'!I11*Missions!$E$6:$E$26*Missions!$J$6:$J$26)+SUMPRODUCT((Missions!$F$6:$F$26="Commission Boost")*(Missions!$A$6:$A$26="Silver")*(Missions!$D$6:$D$26="One-time")*'Affiliate Projection'!I21*Missions!$E$6:$E$26*Missions!$J$6:$J$26)+SUMPRODUCT((Missions!$F$6:$F$26="Commission Boost")*(Missions!$A$6:$A$26="Silver")*(Missions!$D$6:$D$26<>"One-time")*'Affiliate Projection'!I12*Missions!$E$6:$E$26*Missions!$J$6:$J$26)+SUMPRODUCT((Missions!$F$6:$F$26="Commission Boost")*(Missions!$A$6:$A$26="Gold")*(Missions!$D$6:$D$26="One-time")*'Affiliate Projection'!I22*Missions!$E$6:$E$26*Missions!$J$6:$J$26)+SUMPRODUCT((Missions!$F$6:$F$26="Commission Boost")*(Missions!$A$6:$A$26="Gold")*(Missions!$D$6:$D$26<>"One-time")*'Affiliate Projection'!I13*Missions!$E$6:$E$26*Missions!$J$6:$J$26)+SUMPRODUCT((Missions!$F$6:$F$26="Commission Boost")*(Missions!$A$6:$A$26="Platinum")*(Missions!$D$6:$D$26="One-time")*'Affiliate Projection'!I23*Missions!$E$6:$E$26*Missions!$J$6:$J$26)+SUMPRODUCT((Missions!$F$6:$F$26="Commission Boost")*(Missions!$A$6:$A$26="Platinum")*(Missions!$D$6:$D$26<>"One-time")*'Affiliate Projection'!I14*Missions!$E$6:$E$26*Missions!$J$6:$J$26)+SUMPRODUCT((Missions!$F$6:$F$26="Commission Boost")*(Missions!$A$6:$A$26="Diamond")*(Missions!$D$6:$D$26="One-time")*'Affiliate Projection'!I24*Missions!$E$6:$E$26*Missions!$J$6:$J$26)+SUMPRODUCT((Missions!$F$6:$F$26="Commission Boost")*(Missions!$A$6:$A$26="Diamond")*(Missions!$D$6:$D$26<>"One-time")*'Affiliate Projection'!I15*Missions!$E$6:$E$26*Missions!$J$6:$J$26) | ... M7: =SUMPRODUCT((Missions!$F$6:$F$26="Commission Boost")*(Missions!$A$6:$A$26="Bronze")*(Missions!$D$6:$D$26="One-time")*'Affiliate Projection'!M20*Missions!$E$6:$E$26*Missions!$J$6:$J$26)+SUMPRODUCT((Missions!$F$6:$F$26="Commission Boost")*(Missions!$A$6:$A$26="Bronze")*(Missions!$D$6:$D$26<>"One-time")*'Affiliate Projection'!M11*Missions!$E$6:$E$26*Missions!$J$6:$J$26)+SUMPRODUCT((Missions!$F$6:$F$26="Commission Boost")*(Missions!$A$6:$A$26="Silver")*(Missions!$D$6:$D$26="One-time")*'Affiliate Projection'!M21*Missions!$E$6:$E$26*Missions!$J$6:$J$26)+SUMPRODUCT((Missions!$F$6:$F$26="Commission Boost")*(Missions!$A$6:$A$26="Silver")*(Missions!$D$6:$D$26<>"One-time")*'Affiliate Projection'!M12*Missions!$E$6:$E$26*Missions!$J$6:$J$26)+SUMPRODUCT((Missions!$F$6:$F$26="Commission Boost")*(Missions!$A$6:$A$26="Gold")*(Missions!$D$6:$D$26="One-time")*'Affiliate Projection'!M22*Missions!$E$6:$E$26*Missions!$J$6:$J$26)+SUMPRODUCT((Missions!$F$6:$F$26="Commission Boost")*(Missions!$A$6:$A$26="Gold")*(Missions!$D$6:$D$26<>"One-time")*'Affiliate Projection'!M13*Missions!$E$6:$E$26*Missions!$J$6:$J$26)+SUMPRODUCT((Missions!$F$6:$F$26="Commission Boost")*(Missions!$A$6:$A$26="Platinum")*(Missions!$D$6:$D$26="One-time")*'Affiliate Projection'!M23*Missions!$E$6:$E$26*Missions!$J$6:$J$26)+SUMPRODUCT((Missions!$F$6:$F$26="Commission Boost")*(Missions!$A$6:$A$26="Platinum")*(Missions!$D$6:$D$26<>"One-time")*'Affiliate Projection'!M14*Missions!$E$6:$E$26*Missions!$J$6:$J$26)+SUMPRODUCT((Missions!$F$6:$F$26="Commission Boost")*(Missions!$A$6:$A$26="Diamond")*(Missions!$D$6:$D$26="One-time")*'Affiliate Projection'!M24*Missions!$E$6:$E$26*Missions!$J$6:$J$26)+SUMPRODUCT((Missions!$F$6:$F$26="Commission Boost")*(Missions!$A$6:$A$26="Diamond")*(Missions!$D$6:$D$26<>"One-time")*'Affiliate Projection'!M15*Missions!$E$6:$E$26*Missions!$J$6:$J$26)
A8: Discount Cost (Welcome) | B8: ='Affiliate Projection'!B20*'VIP Levels'!$G$14*'VIP Levels'!$E$5*('VIP Levels'!$I$14/30)*'VIP Levels'!$H$14*Inputs!$B$11*Inputs!$B$16+'Affiliate Projection'!B21*'VIP Levels'!$G$15*'VIP Levels'!$E$6*('VIP Levels'!$I$15/30)*'VIP Levels'!$H$15*Inputs!$B$11*Inputs!$B$16+'Affiliate Projection'!B22*'VIP Levels'!$G$16*'VIP Levels'!$E$7*('VIP Levels'!$I$16/30)*'VIP Levels'!$H$16*Inputs!$B$11*Inputs!$B$16+'Affiliate Projection'!B23*'VIP Levels'!$G$17*'VIP Levels'!$E$8*('VIP Levels'!$I$17/30)*'VIP Levels'!$H$17*Inputs!$B$11*Inputs!$B$16+'Affiliate Projection'!B24*'VIP Levels'!$G$18*'VIP Levels'!$E$9*('VIP Levels'!$I$18/30)*'VIP Levels'!$H$18*Inputs!$B$11*Inputs!$B$16 | C8: ='Affiliate Projection'!C20*'VIP Levels'!$G$14*'VIP Levels'!$E$5*('VIP Levels'!$I$14/30)*'VIP Levels'!$H$14*Inputs!$B$11*Inputs!$B$16+'Affiliate Projection'!C21*'VIP Levels'!$G$15*'VIP Levels'!$E$6*('VIP Levels'!$I$15/30)*'VIP Levels'!$H$15*Inputs!$B$11*Inputs!$B$16+'Affiliate Projection'!C22*'VIP Levels'!$G$16*'VIP Levels'!$E$7*('VIP Levels'!$I$16/30)*'VIP Levels'!$H$16*Inputs!$B$11*Inputs!$B$16+'Affiliate Projection'!C23*'VIP Levels'!$G$17*'VIP Levels'!$E$8*('VIP Levels'!$I$17/30)*'VIP Levels'!$H$17*Inputs!$B$11*Inputs!$B$16+'Affiliate Projection'!C24*'VIP Levels'!$G$18*'VIP Levels'!$E$9*('VIP Levels'!$I$18/30)*'VIP Levels'!$H$18*Inputs!$B$11*Inputs!$B$16 | D8: ='Affiliate Projection'!D20*'VIP Levels'!$G$14*'VIP Levels'!$E$5*('VIP Levels'!$I$14/30)*'VIP Levels'!$H$14*Inputs!$B$11*Inputs!$B$16+'Affiliate Projection'!D21*'VIP Levels'!$G$15*'VIP Levels'!$E$6*('VIP Levels'!$I$15/30)*'VIP Levels'!$H$15*Inputs!$B$11*Inputs!$B$16+'Affiliate Projection'!D22*'VIP Levels'!$G$16*'VIP Levels'!$E$7*('VIP Levels'!$I$16/30)*'VIP Levels'!$H$16*Inputs!$B$11*Inputs!$B$16+'Affiliate Projection'!D23*'VIP Levels'!$G$17*'VIP Levels'!$E$8*('VIP Levels'!$I$17/30)*'VIP Levels'!$H$17*Inputs!$B$11*Inputs!$B$16+'Affiliate Projection'!D24*'VIP Levels'!$G$18*'VIP Levels'!$E$9*('VIP Levels'!$I$18/30)*'VIP Levels'!$H$18*Inputs!$B$11*Inputs!$B$16 | E8: ='Affiliate Projection'!E20*'VIP Levels'!$G$14*'VIP Levels'!$E$5*('VIP Levels'!$I$14/30)*'VIP Levels'!$H$14*Inputs!$B$11*Inputs!$B$16+'Affiliate Projection'!E21*'VIP Levels'!$G$15*'VIP Levels'!$E$6*('VIP Levels'!$I$15/30)*'VIP Levels'!$H$15*Inputs!$B$11*Inputs!$B$16+'Affiliate Projection'!E22*'VIP Levels'!$G$16*'VIP Levels'!$E$7*('VIP Levels'!$I$16/30)*'VIP Levels'!$H$16*Inputs!$B$11*Inputs!$B$16+'Affiliate Projection'!E23*'VIP Levels'!$G$17*'VIP Levels'!$E$8*('VIP Levels'!$I$17/30)*'VIP Levels'!$H$17*Inputs!$B$11*Inputs!$B$16+'Affiliate Projection'!E24*'VIP Levels'!$G$18*'VIP Levels'!$E$9*('VIP Levels'!$I$18/30)*'VIP Levels'!$H$18*Inputs!$B$11*Inputs!$B$16 | F8: ='Affiliate Projection'!F20*'VIP Levels'!$G$14*'VIP Levels'!$E$5*('VIP Levels'!$I$14/30)*'VIP Levels'!$H$14*Inputs!$B$11*Inputs!$B$16+'Affiliate Projection'!F21*'VIP Levels'!$G$15*'VIP Levels'!$E$6*('VIP Levels'!$I$15/30)*'VIP Levels'!$H$15*Inputs!$B$11*Inputs!$B$16+'Affiliate Projection'!F22*'VIP Levels'!$G$16*'VIP Levels'!$E$7*('VIP Levels'!$I$16/30)*'VIP Levels'!$H$16*Inputs!$B$11*Inputs!$B$16+'Affiliate Projection'!F23*'VIP Levels'!$G$17*'VIP Levels'!$E$8*('VIP Levels'!$I$17/30)*'VIP Levels'!$H$17*Inputs!$B$11*Inputs!$B$16+'Affiliate Projection'!F24*'VIP Levels'!$G$18*'VIP Levels'!$E$9*('VIP Levels'!$I$18/30)*'VIP Levels'!$H$18*Inputs!$B$11*Inputs!$B$16 | G8: ='Affiliate Projection'!G20*'VIP Levels'!$G$14*'VIP Levels'!$E$5*('VIP Levels'!$I$14/30)*'VIP Levels'!$H$14*Inputs!$B$11*Inputs!$B$16+'Affiliate Projection'!G21*'VIP Levels'!$G$15*'VIP Levels'!$E$6*('VIP Levels'!$I$15/30)*'VIP Levels'!$H$15*Inputs!$B$11*Inputs!$B$16+'Affiliate Projection'!G22*'VIP Levels'!$G$16*'VIP Levels'!$E$7*('VIP Levels'!$I$16/30)*'VIP Levels'!$H$16*Inputs!$B$11*Inputs!$B$16+'Affiliate Projection'!G23*'VIP Levels'!$G$17*'VIP Levels'!$E$8*('VIP Levels'!$I$17/30)*'VIP Levels'!$H$17*Inputs!$B$11*Inputs!$B$16+'Affiliate Projection'!G24*'VIP Levels'!$G$18*'VIP Levels'!$E$9*('VIP Levels'!$I$18/30)*'VIP Levels'!$H$18*Inputs!$B$11*Inputs!$B$16 | H8: ='Affiliate Projection'!H20*'VIP Levels'!$G$14*'VIP Levels'!$E$5*('VIP Levels'!$I$14/30)*'VIP Levels'!$H$14*Inputs!$B$11*Inputs!$B$16+'Affiliate Projection'!H21*'VIP Levels'!$G$15*'VIP Levels'!$E$6*('VIP Levels'!$I$15/30)*'VIP Levels'!$H$15*Inputs!$B$11*Inputs!$B$16+'Affiliate Projection'!H22*'VIP Levels'!$G$16*'VIP Levels'!$E$7*('VIP Levels'!$I$16/30)*'VIP Levels'!$H$16*Inputs!$B$11*Inputs!$B$16+'Affiliate Projection'!H23*'VIP Levels'!$G$17*'VIP Levels'!$E$8*('VIP Levels'!$I$17/30)*'VIP Levels'!$H$17*Inputs!$B$11*Inputs!$B$16+'Affiliate Projection'!H24*'VIP Levels'!$G$18*'VIP Levels'!$E$9*('VIP Levels'!$I$18/30)*'VIP Levels'!$H$18*Inputs!$B$11*Inputs!$B$16 | I8: ='Affiliate Projection'!I20*'VIP Levels'!$G$14*'VIP Levels'!$E$5*('VIP Levels'!$I$14/30)*'VIP Levels'!$H$14*Inputs!$B$11*Inputs!$B$16+'Affiliate Projection'!I21*'VIP Levels'!$G$15*'VIP Levels'!$E$6*('VIP Levels'!$I$15/30)*'VIP Levels'!$H$15*Inputs!$B$11*Inputs!$B$16+'Affiliate Projection'!I22*'VIP Levels'!$G$16*'VIP Levels'!$E$7*('VIP Levels'!$I$16/30)*'VIP Levels'!$H$16*Inputs!$B$11*Inputs!$B$16+'Affiliate Projection'!I23*'VIP Levels'!$G$17*'VIP Levels'!$E$8*('VIP Levels'!$I$17/30)*'VIP Levels'!$H$17*Inputs!$B$11*Inputs!$B$16+'Affiliate Projection'!I24*'VIP Levels'!$G$18*'VIP Levels'!$E$9*('VIP Levels'!$I$18/30)*'VIP Levels'!$H$18*Inputs!$B$11*Inputs!$B$16 | ... M8: ='Affiliate Projection'!M20*'VIP Levels'!$G$14*'VIP Levels'!$E$5*('VIP Levels'!$I$14/30)*'VIP Levels'!$H$14*Inputs!$B$11*Inputs!$B$16+'Affiliate Projection'!M21*'VIP Levels'!$G$15*'VIP Levels'!$E$6*('VIP Levels'!$I$15/30)*'VIP Levels'!$H$15*Inputs!$B$11*Inputs!$B$16+'Affiliate Projection'!M22*'VIP Levels'!$G$16*'VIP Levels'!$E$7*('VIP Levels'!$I$16/30)*'VIP Levels'!$H$16*Inputs!$B$11*Inputs!$B$16+'Affiliate Projection'!M23*'VIP Levels'!$G$17*'VIP Levels'!$E$8*('VIP Levels'!$I$17/30)*'VIP Levels'!$H$17*Inputs!$B$11*Inputs!$B$16+'Affiliate Projection'!M24*'VIP Levels'!$G$18*'VIP Levels'!$E$9*('VIP Levels'!$I$18/30)*'VIP Levels'!$H$18*Inputs!$B$11*Inputs!$B$16
