Workbook
Name AffAttrition: Inputs!$B$10
Name SampleAffConv: Inputs!$B$7

Sheet Inputs
A1: LOYALTY PROGRAM FINANCIAL MODEL - INPUTS DASHBOARD
A3: ACQUISITION INPUTS
A4: Parameter | B4: Value | C4: Unit | D4: Name | E4: Description | G4: Used by
A5: Samples Sent - Month 1 | B5: 150 | C5: samples | E5: Initial month sample distribution | G5: Affiliate Projection | Cell B4
A6: Samples Sent - Month 2+ | B6: 100 | C6: samples | E6: Ongoing monthly sample distribution | G6: Affiliate Projection | Row 4
A7: Sample-to-Affiliate Conversion Rate | B7: 0.7 | C7: % | D7: SampleAffConv | E7: Percentage of samples that convert to affiliates | G7: Affiliate Projection | Row 5
A8: Flywheel Affiliates per Month | B8: 10 | C8: affiliates | E8: Organic inbound affiliates monthly | G8: Won't this be gradual and dynamic? M1 we may have 0, M7 we could have 100
A9: Time to First Sale | B9: 14 | C9: days | E9: Lag between conversion and first sale | G9: Placeholder..
A10: Affiliate Attrition Rate | B10: 0.05 | C10: % | D10: AffAttrition | E10: Monthly churn rate of affiliates | G10: Affiliate Projection | Row 8
A12: PERFORMANCE INPUTS
A13: Parameter | B13: Value | C13: Unit | E13: Description
A14: (DEPRECATED) Average Sales per Affiliate per Month | C14: sales | E14: Monthly sales velocity per active affiliate | G14: How can we make this… dynamic? Some affiliates may sell 2, 5, 10 … by % Perhaps: 30% sell 0 (or attrition) | 40% sell 5 | 20% sell 8 | 10% sell 15
A15: Gross AOV | B15: 100 | C15: $ | E15: Average order value before discounts | G15: Revenue | Row 5 & Missions | Col J
A16: Rolling Window Duration | B16: 30 | C16: days | E16: Time period for VIP level qualification | G16: Placeholder..
A19: REDEMPTION & BEHAVIOR INPUTS
A20: Parameter | B20: Value | C20: Unit | E20: Description
A21: Discount Redemption Rate | B21: 0.3 | C21: % | E21: Percentage of discount coupons redeemed | G21: Revenue | Row 8
A22: Default Mission Completion Rate | B22: 0.25 | C22: % | E22: Default completion rate for missions | G22: Overriden by mission sheet… delete?
A23: (DEPRECATED) Avg Sales During Commission Boost | C23: sales | E23: Expected sales an affiliate makes during boost period | G23: Costs | Rows 6-7 & Misions | Col J
A26: COST INPUTS
A27: Parameter | B27: Value | C27: Unit | E27: Description
A28: Cost per Sample | B28: 15 | C28: $ | E28: Cost of each sample sent (product + shipping) | G28: Costs row 22
A31: LEVEL DISTRIBUTION ASSUMPTIONS
A32: (Estimated % of affiliates at each level based on sales velocity vs thresholds)
A33: Level | B33: % of Affiliates | C33: Description
A34: Bronze | B34: 0.65 | C34: Affiliates below Silver threshold | G34: This is static through time? We assume each month we will have this breakdown?
A35: Silver | B35: 0.2 | C35: Affiliates at Silver, below Gold
A36: Gold | B36: 0.1 | C36: Affiliates at Gold, below Platinum
A37: Platinum | B37: 0.05 | C37: Affiliates at Platinum, below Diamond
A38: Diamond | B38: 0 | C38: Top performers at Diamond
A39: Total (must = 100%) | B39: =SUM(B34:B38) -> 1
A42: LEGEND
A43: Yellow cells | B43: =Editable inputs -> #NAME?
A44: Green cells | B44: =Calculated values -> #NAME?

Sheet VIP Levels
A1: VIP LEVEL CONFIGURATION
A3: LEVEL THRESHOLDS & COMMISSION
A4: Level # | B4: Name | C4: Sales Threshold | D4: Base Commission % | E4: Avg Sales/Month
A5: 1 | B5: Bronze | C5: 0 | D5: 0.1 | E5: 2
A6: 2 | B6: Silver | C6: 5 | D6: 0.12 | E6: 6
A7: 3 | B7: Gold | C7: 20 | D7: 0.18 | E7: 12
A8: 4 | B8: Platinum | C8: 50 | D8: 0.22 | E8: 25
A9: 5 | B9: Diamond | C9: 100 | D9: 0.25 | E9: 50
A12: WELCOME REWARDS (Per Level)
A13: Level | B13: Comm Boost Qty | C13: Comm Boost % | D13: Comm Boost Days | E13: Gift Card Qty | F13: Gift Card $ | G13: Discount Qty | H13: Discount % | I13: Spark Ads Qty | J13: Spark Ads $ | K13: Phys Gift Qty | L13: Phys Gift $ | M13: Experience Qty | N13: Experience $
A14: Bronze | B14: 1 | C14: 0.1 | D14: 30 | E14: 0 | F14: 0 | G14: 2 | H14: 0.15 | I14: 0 | J14: 0 | K14: 0 | L14: 0 | M14: 0 | N14: 0
A15: Silver | B15: 2 | C15: 0.15 | D15: 30 | E15: 1 | F15: 50 | G15: 2 | H15: 0.15 | I15: 1 | J15: 25 | K15: 0 | L15: 0 | M15: 0 | N15: 0
A16: Yes | B16: 1 | C16: 0.2 | D16: 30 | E16: 1 | F16: 100 | G16: 2 | H16: 0.2 | I16: 1 | J16: 50 | K16: 1 | L16: 50 | M16: 0 | N16: 0
A17: Platinum | B17: 2 | C17: 0.25 | D17: 45 | E17: 2 | F17: 150 | G17: 3 | H17: 0.25 | I17: 2 | J17: 75 | K17: 1 | L17: 75 | M17: 1 | N17: 100
A18: Diamond | B18: 3 | C18: 0.3 | D18: 60 | E18: 2 | F18: 200 | G18: 3 | H18: 0.3 | I18: 2 | J18: 100 | K18: 1 | L18: 100 | M18: 1 | N18: 200
A21: WELCOME REWARD SUMMARY (Weighted by Level Distribution)
A22: Weighted Avg Commission Boost % | B22: =SUMPRODUCT(C14:C18,Inputs!$B$34:$B$38) -> 0.1275
A23: Weighted Avg Gift Card Value | B23: {=SUMPRODUCT(E14:E18*F14:F18,Inputs!$B$34:$B$38)} -> 35
A24: Weighted Avg Spark Ads Value | B24: =SUMPRODUCT(I14:I18*J14:J18,Inputs!$B$34:$B$38) -> 17.5
A25: Weighted Avg Physical Gift Value | B25: =SUMPRODUCT(K14:K18*L14:L18,Inputs!$B$34:$B$38) -> 8.75
A26: Weighted Avg Experience Value | B26: =SUMPRODUCT(M14:M18*N14:N18,Inputs!$B$34:$B$38) -> 5

Sheet Missions
A1: MISSION CONFIGURATION
A3: MISSIONS BY VIP LEVEL
A4: VIP Level | B4: Mission Type | C4: Target | D4: Repeatability | E4: Completion Rate | F4: Reward Type | G4: Reward Value | H4: Reward Duration | I4: Active? | J4: Cost per Completion
A5: Bronze | B5: Sales | C5: 10 | D5: One-time | E5: 0.5 | F5: Gift Card | G5: 25 | H5: 0 | I5: Yes | J5: =IF(F5="Gift Card",G5,IF(F5="Spark Ads",G5,IF(F5="Commission Boost",G5*(INDEX('VIP Levels'!$E$5:$E$9,MATCH(A5,'VIP Levels'!$B$5:$B$9,0))/30*H5)*Revenue!$B$10,IF(F5="Discount",G5*(INDEX('VIP Levels'!$E$5:$E$9,MATCH(A5,'VIP Levels'!$B$5:$B$9,0))/30*H5)*Inputs!$B$15*Inputs!$B$21,0)))) -> 25
A6: Bronze | B6: Videos | C6: 5 | D6: One-time | E6: 0.8 | F6: Gift Card | G6: 25 | H6: 0 | I6: Yes | J6: =IF(F6="Gift Card",G6,IF(F6="Spark Ads",G6,IF(F6="Commission Boost",G6*(INDEX('VIP Levels'!$E$5:$E$9,MATCH(A6,'VIP Levels'!$B$5:$B$9,0))/30*H6)*Revenue!$B$10,IF(F6="Discount",G6*(INDEX('VIP Levels'!$E$5:$E$9,MATCH(A6,'VIP Levels'!$B$5:$B$9,0))/30*H6)*Inputs!$B$15*Inputs!$B$21,0)))) -> 25
A7: Bronze | B7: Views | C7: 2000 | D7: One-time | E7: 0.9 | F7: Discount | G7: 0.15 | H7: 0 | I7: Yes | J7: =IF(F7="Gift Card",G7,IF(F7="Spark Ads",G7,IF(F7="Commission Boost",G7*(INDEX('VIP Levels'!$E$5:$E$9,MATCH(A7,'VIP Levels'!$B$5:$B$9,0))/30*H7)*Revenue!$B$10,IF(F7="Discount",G7*(INDEX('VIP Levels'!$E$5:$E$9,MATCH(A7,'VIP Levels'!$B$5:$B$9,0))/30*H7)*Inputs!$B$15*Inputs!$B$21,0)))) -> 0
A8: Silver | B8: Sales | C8: 15 | D8: Monthly | E8: 0.6 | F8: Gift Card | G8: 50 | H8: 0 | I8: Yes | J8: =IF(F8="Gift Card",G8,IF(F8="Spark Ads",G8,IF(F8="Commission Boost",G8*(INDEX('VIP Levels'!$E$5:$E$9,MATCH(A8,'VIP Levels'!$B$5:$B$9,0))/30*H8)*Revenue!$B$10,IF(F8="Discount",G8*(INDEX('VIP Levels'!$E$5:$E$9,MATCH(A8,'VIP Levels'!$B$5:$B$9,0))/30*H8)*Inputs!$B$15*Inputs!$B$21,0)))) -> 50
A9: Silver | B9: Videos | C9: 15 | D9: Monthly | E9: 0.6 | F9: Commission Boost | G9: 0.1 | H9: 7 | I9: Yes | J9: =IF(F9="Gift Card",G9,IF(F9="Spark Ads",G9,IF(F9="Commission Boost",G9*(INDEX('VIP Levels'!$E$5:$E$9,MATCH(A9,'VIP Levels'!$B$5:$B$9,0))/30*H9)*Revenue!$B$10,IF(F9="Discount",G9*(INDEX('VIP Levels'!$E$5:$E$9,MATCH(A9,'VIP Levels'!$B$5:$B$9,0))/30*H9)*Inputs!$B$15*Inputs!$B$21,0)))) -> 13.328
A10: Silver | B10: Views | C10: 10000 | D10: Monthly | E10: 0.8 | F10: Discount | G10: 0.1 | H10: 2 | I10: Yes | J10: =IF(F10="Gift Card",G10,IF(F10="Spark Ads",G10,IF(F10="Commission Boost",G10*(INDEX('VIP Levels'!$E$5:$E$9,MATCH(A10,'VIP Levels'!$B$5:$B$9,0))/30*H10)*Revenue!$B$10,IF(F10="Discount",G10*(INDEX('VIP Levels'!$E$5:$E$9,MATCH(A10,'VIP Levels'!$B$5:$B$9,0))/30*H10)*Inputs!$B$15*Inputs!$B$21,0)))) -> 1.2
A11: Gold | B11: Sales | C11: 40 | D11: Monthly | E11: 0.5 | F11: Gift Card | G11: 150 | H11: 0 | I11: Yes | J11: =IF(F11="Gift Card",G11,IF(F11="Spark Ads",G11,IF(F11="Commission Boost",G11*(INDEX('VIP Levels'!$E$5:$E$9,MATCH(A11,'VIP Levels'!$B$5:$B$9,0))/30*H11)*Revenue!$B$10,IF(F11="Discount",G11*(INDEX('VIP Levels'!$E$5:$E$9,MATCH(A11,'VIP Levels'!$B$5:$B$9,0))/30*H11)*Inputs!$B$15*Inputs!$B$21,0)))) -> 150
A12: Gold | B12: Views | C12: 20000 | D12: Weekly | E12: 0.7 | F12: Discount | G12: 0.1 | H12: 2 | I12: Yes | J12: =IF(F12="Gift Card",G12,IF(F12="Spark Ads",G12,IF(F12="Commission Boost",G12*(INDEX('VIP Levels'!$E$5:$E$9,MATCH(A12,'VIP Levels'!$B$5:$B$9,0))/30*H12)*Revenue!$B$10,IF(F12="Discount",G12*(INDEX('VIP Levels'!$E$5:$E$9,MATCH(A12,'VIP Levels'!$B$5:$B$9,0))/30*H12)*Inputs!$B$15*Inputs!$B$21,0)))) -> 2.4
A13: Gold | B13: Videos | C13: 20 | D13: Monthly | E13: 0.7 | F13: Commission Boost | G13: 0.1 | H13: 7 | I13: Yes | J13: =IF(F13="Gift Card",G13,IF(F13="Spark Ads",G13,IF(F13="Commission Boost",G13*(INDEX('VIP Levels'!$E$5:$E$9,MATCH(A13,'VIP Levels'!$B$5:$B$9,0))/30*H13)*Revenue!$B$10,IF(F13="Discount",G13*(INDEX('VIP Levels'!$E$5:$E$9,MATCH(A13,'VIP Levels'!$B$5:$B$9,0))/30*H13)*Inputs!$B$15*Inputs!$B$21,0)))) -> 26.656
A14: Platinum | B14: Sales | C14: 100 | D14: Monthly | E14: 0.4 | F14: Gift Card | G14: 400 | H14: 0 | I14: Yes | J14: =IF(F14="Gift Card",G14,IF(F14="Spark Ads",G14,IF(F14="Commission Boost",G14*(INDEX('VIP Levels'!$E$5:$E$9,MATCH(A14,'VIP Levels'!$B$5:$B$9,0))/30*H14)*Revenue!$B$10,IF(F14="Discount",G14*(INDEX('VIP Levels'!$E$5:$E$9,MATCH(A14,'VIP Levels'!$B$5:$B$9,0))/30*H14)*Inputs!$B$15*Inputs!$B$21,0)))) -> 400
A15: Platinum | B15: Videos | C15: 10 | D15: Weekly | E15: 0.7 | F15: Commission Boost | G15: 0.15 | H15: 7 | I15: Yes | J15: =IF(F15="Gift Card",G15,IF(F15="Spark Ads",G15,IF(F15="Commission Boost",G15*(INDEX('VIP Levels'!$E$5:$E$9,MATCH(A15,'VIP Levels'!$B$5:$B$9,0))/30*H15)*Revenue!$B$10,IF(F15="Discount",G15*(INDEX('VIP Levels'!$E$5:$E$9,MATCH(A15,'VIP Levels'!$B$5:$B$9,0))/30*H15)*Inputs!$B$15*Inputs!$B$21,0)))) -> 83.3
A16: Platinum | B16: Views | C16: 20000 | D16: Weekly | E16: 0.5 | F16: Discount | G16: 0.15 | H16: 2 | I16: Yes | J16: =IF(F16="Gift Card",G16,IF(F16="Spark Ads",G16,IF(F16="Commission Boost",G16*(INDEX('VIP Levels'!$E$5:$E$9,MATCH(A16,'VIP Levels'!$B$5:$B$9,0))/30*H16)*Revenue!$B$10,IF(F16="Discount",G16*(INDEX('VIP Levels'!$E$5:$E$9,MATCH(A16,'VIP Levels'!$B$5:$B$9,0))/30*H16)*Inputs!$B$15*Inputs!$B$21,0)))) -> 7.5
J17: =IF(F17="Gift Card",G17,IF(F17="Spark Ads",G17,IF(F17="Commission Boost",G17*(INDEX('VIP Levels'!$E$5:$E$9,MATCH(A17,'VIP Levels'!$B$5:$B$9,0))/30*H17)*Revenue!$B$10,IF(F17="Discount",G17*(INDEX('VIP Levels'!$E$5:$E$9,MATCH(A17,'VIP Levels'!$B$5:$B$9,0))/30*H17)*Inputs!$B$15*Inputs!$B$21,0)))) -> 0
J18: =IF(F18="Gift Card",G18,IF(F18="Spark Ads",G18,IF(F18="Commission Boost",G18*(INDEX('VIP Levels'!$E$5:$E$9,MATCH(A18,'VIP Levels'!$B$5:$B$9,0))/30*H18)*Revenue!$B$10,IF(F18="Discount",G18*(INDEX('VIP Levels'!$E$5:$E$9,MATCH(A18,'VIP Levels'!$B$5:$B$9,0))/30*H18)*Inputs!$B$15*Inputs!$B$21,0)))) -> 0
J19: =IF(F19="Gift Card",G19,IF(F19="Spark Ads",G19,IF(F19="Commission Boost",G19*(INDEX('VIP Levels'!$E$5:$E$9,MATCH(A19,'VIP Levels'!$B$5:$B$9,0))/30*H19)*Revenue!$B$10,IF(F19="Discount",G19*(INDEX('VIP Levels'!$E$5:$E$9,MATCH(A19,'VIP Levels'!$B$5:$B$9,0))/30*H19)*Inputs!$B$15*Inputs!$B$21,0)))) -> 0
J20: =IF(F20="Gift Card",G20,IF(F20="Spark Ads",G20,IF(F20="Commission Boost",G20*(INDEX('VIP Levels'!$E$5:$E$9,MATCH(A20,'VIP Levels'!$B$5:$B$9,0))/30*H20)*Revenue!$B$10,IF(F20="Discount",G20*(INDEX('VIP Levels'!$E$5:$E$9,MATCH(A20,'VIP Levels'!$B$5:$B$9,0))/30*H20)*Inputs!$B$15*Inputs!$B$21,0)))) -> 0
J21: =IF(F21="Gift Card",G21,IF(F21="Spark Ads",G21,IF(F21="Commission Boost",G21*(INDEX('VIP Levels'!$E$5:$E$9,MATCH(A21,'VIP Levels'!$B$5:$B$9,0))/30*H21)*Revenue!$B$10,IF(F21="Discount",G21*(INDEX('VIP Levels'!$E$5:$E$9,MATCH(A21,'VIP Levels'!$B$5:$B$9,0))/30*H21)*Inputs!$B$15*Inputs!$B$21,0)))) -> 0
J22: =IF(F22="Gift Card",G22,IF(F22="Spark Ads",G22,IF(F22="Commission Boost",G22*(INDEX('VIP Levels'!$E$5:$E$9,MATCH(A22,'VIP Levels'!$B$5:$B$9,0))/30*H22)*Revenue!$B$10,IF(F22="Discount",G22*(INDEX('VIP Levels'!$E$5:$E$9,MATCH(A22,'VIP Levels'!$B$5:$B$9,0))/30*H22)*Inputs!$B$15*Inputs!$B$21,0)))) -> 0
J23: =IF(F23="Gift Card",G23,IF(F23="Spark Ads",G23,IF(F23="Commission Boost",G23*(INDEX('VIP Levels'!$E$5:$E$9,MATCH(A23,'VIP Levels'!$B$5:$B$9,0))/30*H23)*Revenue!$B$10,IF(F23="Discount",G23*(INDEX('VIP Levels'!$E$5:$E$9,MATCH(A23,'VIP Levels'!$B$5:$B$9,0))/30*H23)*Inputs!$B$15*Inputs!$B$21,0)))) -> 0
J24: =IF(F24="Gift Card",G24,IF(F24="Spark Ads",G24,IF(F24="Commission Boost",G24*(INDEX('VIP Levels'!$E$5:$E$9,MATCH(A24,'VIP Levels'!$B$5:$B$9,0))/30*H24)*Revenue!$B$10,IF(F24="Discount",G24*(INDEX('VIP Levels'!$E$5:$E$9,MATCH(A24,'VIP Levels'!$B$5:$B$9,0))/30*H24)*Inputs!$B$15*Inputs!$B$21,0)))) -> 0
J25: =IF(F25="Gift Card",G25,IF(F25="Spark Ads",G25,IF(F25="Commission Boost",G25*INDEX('VIP Levels'!$E$5:$E$9,MATCH(A25,'VIP Levels'!$B$5:$B$9,0))*Revenue!$B$10,0))) -> 0
J26: =IF(F26="Gift Card",G26,IF(F26="Spark Ads",G26,IF(F26="Commission Boost",G26*INDEX('VIP Levels'!$E$5:$E$9,MATCH(A26,'VIP Levels'!$B$5:$B$9,0))*Revenue!$B$10,0))) -> 0
A29: MISSION SUMMARY BY LEVEL
A30: Level | B30: Active Missions | C30: Avg Completion Rate | D30: Avg Cost per Completion
A31: Bronze | B31: =COUNTIFS(A$6:A$26,A31,I$6:I$26,"Yes") -> 2 | C31: =IFERROR(AVERAGEIFS(E$6:E$26,A$6:A$26,A31,I$6:I$26,"Yes"),0) -> 0.85 | D31: =IFERROR(AVERAGEIFS(J$6:J$26,A$6:A$26,A31,I$6:I$26,"Yes"),0) -> 12.5
A32: Silver | B32: =COUNTIFS(A$6:A$26,A32,I$6:I$26,"Yes") -> 3 | C32: =IFERROR(AVERAGEIFS(E$6:E$26,A$6:A$26,A32,I$6:I$26,"Yes"),0) -> 0.66666667 | D32: =IFERROR(AVERAGEIFS(J$6:J$26,A$6:A$26,A32,I$6:I$26,"Yes"),0) -> 21.509333
A33: Gold | B33: =COUNTIFS(A$6:A$26,A33,I$6:I$26,"Yes") -> 3 | C33: =IFERROR(AVERAGEIFS(E$6:E$26,A$6:A$26,A33,I$6:I$26,"Yes"),0) -> 0.63333333 | D33: =IFERROR(AVERAGEIFS(J$6:J$26,A$6:A$26,A33,I$6:I$26,"Yes"),0) -> 59.685333
A34: Platinum | B34: =COUNTIFS(A$6:A$26,A34,I$6:I$26,"Yes") -> 3 | C34: =IFERROR(AVERAGEIFS(E$6:E$26,A$6:A$26,A34,I$6:I$26,"Yes"),0) -> 0.53333333 | D34: =IFERROR(AVERAGEIFS(J$6:J$26,A$6:A$26,A34,I$6:I$26,"Yes"),0) -> 163.6
A35: Diamond | B35: =COUNTIFS(A$6:A$26,A35,I$6:I$26,"Yes") -> 0 | C35: =IFERROR(AVERAGEIFS(E$6:E$26,A$6:A$26,A35,I$6:I$26,"Yes"),0) -> 0 | D35: =IFERROR(AVERAGEIFS(J$6:J$26,A$6:A$26,A35,I$6:I$26,"Yes"),0) -> 0
A39: Mission Types: Videos, Likes, Sales, Views
A40: Repeatability: One-time, Weekly, Monthly
A41: Reward Types: Gift Card, Commission Boost, Spark Ads

Sheet Affiliate Projection
A1: AFFILIATE PROJECTION (12 MONTHS)
A3: Metric | B3: Month 1 | C3: Month 2 | D3: Month 3 | E3: Month 4 | F3: Month 5 | G3: Month 6 | H3: Month 7 | I3: Month 8 | J3: Month 9 | K3: Month 10 | L3: Month 11 | M3: Month 12
A4: Samples Sent | B4: =Inputs!$B$5 -> 150 | C4: =Inputs!$B$6 -> 100 | D4: =Inputs!$B$6 -> 100 | E4: =Inputs!$B$6 -> 100 | F4: =Inputs!$B$6 -> 100 | G4: =Inputs!$B$6 -> 100 | H4: =Inputs!$B$6 -> 100 | I4: =Inputs!$B$6 -> 100 | J4: =Inputs!$B$6 -> 100 | ... M4: =Inputs!$B$6 -> 100
A5: New Affiliates (from Samples) | B5: {=ROUND(B4*SampleAffConv,0)} -> 105 | C5: =ROUND(C4*SampleAffConv,0) -> 70 | D5: =ROUND(D4*SampleAffConv,0) -> 70 | E5: =ROUND(E4*SampleAffConv,0) -> 70 | F5: =ROUND(F4*SampleAffConv,0) -> 70 | G5: =ROUND(G4*SampleAffConv,0) -> 70 | H5: =ROUND(H4*SampleAffConv,0) -> 70 | I5: =ROUND(I4*SampleAffConv,0) -> 70 | J5: =ROUND(J4*SampleAffConv,0) -> 70 | ... M5: =ROUND(M4*SampleAffConv,0) -> 70
A6: Flywheel Affiliates | B6: =Inputs!$B$8 -> 10 | C6: =Inputs!$B$8 -> 10 | D6: =Inputs!$B$8 -> 10 | E6: =Inputs!$B$8 -> 10 | F6: =Inputs!$B$8 -> 10 | G6: =Inputs!$B$8 -> 10 | H6: =Inputs!$B$8 -> 10 | I6: =Inputs!$B$8 -> 10 | ... M6: =Inputs!$B$8 -> 10
A7: Total New Affiliates | B7: =B5+B6 -> 115 | C7: =C5+C6 -> 80 | D7: =D5+D6 -> 80 | E7: =E5+E6 -> 80 | F7: =F5+F6 -> 80 | G7: =G5+G6 -> 80 | H7: =H5+H6 -> 80 | I7: =I5+I6 -> 80 | ... M7: =M5+M6 -> 80 | Q7: s
A8: Churned Affiliates | B8: 0 | C8: =ROUND(B9*AffAttrition,0) -> 6 | D8: =ROUND(C9*AffAttrition,0) -> 9 | E8: =ROUND(D9*AffAttrition,0) -> 13 | F8: =ROUND(E9*AffAttrition,0) -> 16 | G8: =ROUND(F9*AffAttrition,0) -> 20 | H8: =ROUND(G9*AffAttrition,0) -> 23 | I8: =ROUND(H9*AffAttrition,0) -> 25 | J8: =ROUND(I9*AffAttrition,0) -> 28 | ... M8: =ROUND(L9*AffAttrition,0) -> 36
A9: Active Affiliates (End of Month) | B9: =B7-B8 -> 115 | C9: =B9+C7-C8 -> 189 | D9: =C9+D7-D8 -> 260 | E9: =D9+E7-E8 -> 327 | F9: =E9+F7-F8 -> 391 | G9: =F9+G7-G8 -> 451 | H9: =G9+H7-H8 -> 508 | I9: =H9+I7-I8 -> 563 | J9: =I9+J7-J8 -> 615 | ... M9: =L9+M7-M8 -> 755
A10: Total Sales | B10: =ROUND(B12*'VIP Levels'!$E$5+B13*'VIP Levels'!$E$6+B14*'VIP Levels'!$E$7+B15*'VIP Levels'!$E$8+B16*'VIP Levels'!$E$9,0) -> 230 | C10: =ROUND(C12*'VIP Levels'!$E$5+C13*'VIP Levels'!$E$6+C14*'VIP Levels'!$E$7+C15*'VIP Levels'!$E$8+C16*'VIP Levels'!$E$9,0) -> 927 | D10: =ROUND(D12*'VIP Levels'!$E$5+D13*'VIP Levels'!$E$6+D14*'VIP Levels'!$E$7+D15*'VIP Levels'!$E$8+D16*'VIP Levels'!$E$9,0) -> 1287 | E10: =ROUND(E12*'VIP Levels'!$E$5+E13*'VIP Levels'!$E$6+E14*'VIP Levels'!$E$7+E15*'VIP Levels'!$E$8+E16*'VIP Levels'!$E$9,0) -> 1612 | F10: =ROUND(F12*'VIP Levels'!$E$5+F13*'VIP Levels'!$E$6+F14*'VIP Levels'!$E$7+F15*'VIP Levels'!$E$8+F16*'VIP Levels'!$E$9,0) -> 1944 | G10: =ROUND(G12*'VIP Levels'!$E$5+G13*'VIP Levels'!$E$6+G14*'VIP Levels'!$E$7+G15*'VIP Levels'!$E$8+G16*'VIP Levels'!$E$9,0) -> 2241 | H10: =ROUND(H12*'VIP Levels'!$E$5+H13*'VIP Levels'!$E$6+H14*'VIP Levels'!$E$7+H15*'VIP Levels'!$E$8+H16*'VIP Levels'!$E$9,0) -> 2509 | I10: =ROUND(I12*'VIP Levels'!$E$5+I13*'VIP Levels'!$E$6+I14*'VIP Levels'!$E$7+I15*'VIP Levels'!$E$8+I16*'VIP Levels'!$E$9,0) -> 2782 | ... M10: =ROUND(M12*'VIP Levels'!$E$5+M13*'VIP Levels'!$E$6+M14*'VIP Levels'!$E$7+M15*'VIP Levels'!$E$8+M16*'VIP Levels'!$E$9,0) -> 3750
A11: --- Level Distribution ---
A12: Affiliates at Bronze | B12: =B9 -> 115 | C12: =ROUND(C9*Inputs!$B$34,0) -> 123 | D12: =ROUND(D9*Inputs!$B$34,0) -> 169 | E12: =ROUND(E9*Inputs!$B$34,0) -> 213 | F12: =ROUND(F9*Inputs!$B$34,0) -> 254 | G12: =ROUND(G9*Inputs!$B$34,0) -> 293 | H12: =ROUND(H9*Inputs!$B$34,0) -> 330 | I12: =ROUND(I9*Inputs!$B$34,0) -> 366 | J12: =ROUND(J9*Inputs!$B$34,0) -> 400 | ... M12: =ROUND(M9*Inputs!$B$34,0) -> 491
A13: Affiliates at Silver | B13: 0 | C13: =ROUND(C9*Inputs!$B$35,0) -> 38 | D13: =ROUND(D9*Inputs!$B$35,0) -> 52 | E13: =ROUND(E9*Inputs!$B$35,0) -> 65 | F13: =ROUND(F9*Inputs!$B$35,0) -> 78 | G13: =ROUND(G9*Inputs!$B$35,0) -> 90 | H13: =ROUND(H9*Inputs!$B$35,0) -> 102 | I13: =ROUND(I9*Inputs!$B$35,0) -> 113 | J13: =ROUND(J9*Inputs!$B$35,0) -> 123 | ... M13: =ROUND(M9*Inputs!$B$35,0) -> 151
A14: Affiliates at Gold | B14: 0 | C14: =ROUND(C9*Inputs!$B$36,0) -> 19 | D14: =ROUND(D9*Inputs!$B$36,0) -> 26 | E14: =ROUND(E9*Inputs!$B$36,0) -> 33 | F14: =ROUND(F9*Inputs!$B$36,0) -> 39 | G14: =ROUND(G9*Inputs!$B$36,0) -> 45 | H14: =ROUND(H9*Inputs!$B$36,0) -> 51 | I14: =ROUND(I9*Inputs!$B$36,0) -> 56 | J14: =ROUND(J9*Inputs!$B$36,0) -> 62 | ... M14: =ROUND(M9*Inputs!$B$36,0) -> 76
A15: Affiliates at Platinum | B15: 0 | C15: =ROUND(C9*Inputs!$B$37,0) -> 9 | D15: =ROUND(D9*Inputs!$B$37,0) -> 13 | E15: =ROUND(E9*Inputs!$B$37,0) -> 16 | F15: =ROUND(F9*Inputs!$B$37,0) -> 20 | G15: =ROUND(G9*Inputs!$B$37,0) -> 23 | H15: =ROUND(H9*Inputs!$B$37,0) -> 25 | I15: =ROUND(I9*Inputs!$B$37,0) -> 28 | J15: =ROUND(J9*Inputs!$B$37,0) -> 31 | ... M15: =ROUND(M9*Inputs!$B$37,0) -> 38
A16: Affiliates at Diamond | B16: 0 | C16: =ROUND(C9*Inputs!$B$38,0) -> 0 | D16: =ROUND(D9*Inputs!$B$38,0) -> 0 | E16: =ROUND(E9*Inputs!$B$38,0) -> 0 | F16: =ROUND(F9*Inputs!$B$38,0) -> 0 | G16: =ROUND(G9*Inputs!$B$38,0) -> 0 | H16: =ROUND(H9*Inputs!$B$38,0) -> 0 | I16: =ROUND(I9*Inputs!$B$38,0) -> 0 | J16: =ROUND(J9*Inputs!$B$38,0) -> 0 | ... M16: =ROUND(M9*Inputs!$B$38,0) -> 0
A17: --- Level Events ---
A18: New Affiliate Level-Ups (to Bronze) | B18: =B7 -> 115 | C18: =C7 -> 80 | D18: =D7 -> 80 | E18: =E7 -> 80 | F18: =F7 -> 80 | G18: =G7 -> 80 | H18: =H7 -> 80 | I18: =I7 -> 80 | ... M18: =M7 -> 80
A19: Promotion Events (Bronze to higher) | B19: 0 | C19: =MAX(0,(C13+C14+C15+C16)-(B13+B14+B15+B16)) -> 66 | D19: =MAX(0,(D13+D14+D15+D16)-(C13+C14+C15+C16)) -> 25 | E19: =MAX(0,(E13+E14+E15+E16)-(D13+D14+D15+D16)) -> 23 | F19: =MAX(0,(F13+F14+F15+F16)-(E13+E14+E15+E16)) -> 23 | G19: =MAX(0,(G13+G14+G15+G16)-(F13+F14+F15+F16)) -> 21 | H19: =MAX(0,(H13+H14+H15+H16)-(G13+G14+G15+G16)) -> 20 | I19: =MAX(0,(I13+I14+I15+I16)-(H13+H14+H15+H16)) -> 19 | J19: =MAX(0,(J13+J14+J15+J16)-(I13+I14+I15+I16)) -> 19 | ... M19: =MAX(0,(M13+M14+M15+M16)-(L13+L14+L15+L16)) -> 16
A20: Total Level-Up Events | B20: =B18+B19 -> 115 | C20: =C18+C19 -> 146 | D20: =D18+D19 -> 105 | E20: =E18+E19 -> 103 | F20: =F18+F19 -> 103 | G20: =G18+G19 -> 101 | H20: =H18+H19 -> 100 | I20: =I18+I19 -> 99 | ... M20: =M18+M19 -> 96
A21: Demotion Events | B21: 0 | C21: =MAX(0,(B13+B14+B15+B16)-(C13+C14+C15+C16)) -> 0 | D21: =MAX(0,(C13+C14+C15+C16)-(D13+D14+D15+D16)) -> 0 | E21: =MAX(0,(D13+D14+D15+D16)-(E13+E14+E15+E16)) -> 0 | F21: =MAX(0,(E13+E14+E15+E16)-(F13+F14+F15+F16)) -> 0 | G21: =MAX(0,(F13+F14+F15+F16)-(G13+G14+G15+G16)) -> 0 | H21: =MAX(0,(G13+G14+G15+G16)-(H13+H14+H15+H16)) -> 0 | I21: =MAX(0,(H13+H14+H15+H16)-(I13+I14+I15+I16)) -> 0 | J21: =MAX(0,(I13+I14+I15+I16)-(J13+J14+J15+J16)) -> 0 | ... M21: =MAX(0,(L13+L14+L15+L16)-(M13+M14+M15+M16)) -> 0

Sheet Reward Triggers
A1: REWARD TRIGGERS (12 MONTHS)
A3: Metric | B3: Month 1 | C3: Month 2 | D3: Month 3 | E3: Month 4 | F3: Month 5 | G3: Month 6 | H3: Month 7 | I3: Month 8 | J3: Month 9 | K3: Month 10 | L3: Month 11 | M3: Month 12
A4: --- WELCOME REWARDS (per level-up) ---
A5: Commission Boosts Triggered | B5: =ROUND('Affiliate Projection'!B18*'VIP Levels'!$B$14+'Affiliate Projection'!B19*IFERROR(SUMPRODUCT('VIP Levels'!$B$15:$B$18,Inputs!$B$35:$B$38)/SUM(Inputs!$B$35:$B$38),0),0) -> 115 | C5: =ROUND('Affiliate Projection'!C18*'VIP Levels'!$B$14+'Affiliate Projection'!C19*IFERROR(SUMPRODUCT('VIP Levels'!$B$15:$B$18,Inputs!$B$35:$B$38)/SUM(Inputs!$B$35:$B$38),0),0) -> 193 | D5: =ROUND('Affiliate Projection'!D18*'VIP Levels'!$B$14+'Affiliate Projection'!D19*IFERROR(SUMPRODUCT('VIP Levels'!$B$15:$B$18,Inputs!$B$35:$B$38)/SUM(Inputs!$B$35:$B$38),0),0) -> 123 | E5: =ROUND('Affiliate Projection'!E18*'VIP Levels'!$B$14+'Affiliate Projection'!E19*IFERROR(SUMPRODUCT('VIP Levels'!$B$15:$B$18,Inputs!$B$35:$B$38)/SUM(Inputs!$B$35:$B$38),0),0) -> 119 | F5: =ROUND('Affiliate Projection'!F18*'VIP Levels'!$B$14+'Affiliate Projection'!F19*IFERROR(SUMPRODUCT('VIP Levels'!$B$15:$B$18,Inputs!$B$35:$B$38)/SUM(Inputs!$B$35:$B$38),0),0) -> 119 | G5: =ROUND('Affiliate Projection'!G18*'VIP Levels'!$B$14+'Affiliate Projection'!G19*IFERROR(SUMPRODUCT('VIP Levels'!$B$15:$B$18,Inputs!$B$35:$B$38)/SUM(Inputs!$B$35:$B$38),0),0) -> 116 | H5: =ROUND('Affiliate Projection'!H18*'VIP Levels'!$B$14+'Affiliate Projection'!H19*IFERROR(SUMPRODUCT('VIP Levels'!$B$15:$B$18,Inputs!$B$35:$B$38)/SUM(Inputs!$B$35:$B$38),0),0) -> 114 | I5: =ROUND('Affiliate Projection'!I18*'VIP Levels'!$B$14+'Affiliate Projection'!I19*IFERROR(SUMPRODUCT('VIP Levels'!$B$15:$B$18,Inputs!$B$35:$B$38)/SUM(Inputs!$B$35:$B$38),0),0) -> 113 | ... M5: =ROUND('Affiliate Projection'!M18*'VIP Levels'!$B$14+'Affiliate Projection'!M19*IFERROR(SUMPRODUCT('VIP Levels'!$B$15:$B$18,Inputs!$B$35:$B$38)/SUM(Inputs!$B$35:$B$38),0),0) -> 107
A6: Gift Cards Triggered | B6: =ROUND('Affiliate Projection'!B18*'VIP Levels'!$E$14+'Affiliate Projection'!B19*IFERROR(SUMPRODUCT('VIP Levels'!$E$15:$E$18,Inputs!$B$35:$B$38)/SUM(Inputs!$B$35:$B$38),0),0) -> 0 | C6: =ROUND('Affiliate Projection'!C18*'VIP Levels'!$E$14+'Affiliate Projection'!C19*IFERROR(SUMPRODUCT('VIP Levels'!$E$15:$E$18,Inputs!$B$35:$B$38)/SUM(Inputs!$B$35:$B$38),0),0) -> 75 | D6: =ROUND('Affiliate Projection'!D18*'VIP Levels'!$E$14+'Affiliate Projection'!D19*IFERROR(SUMPRODUCT('VIP Levels'!$E$15:$E$18,Inputs!$B$35:$B$38)/SUM(Inputs!$B$35:$B$38),0),0) -> 29 | E6: =ROUND('Affiliate Projection'!E18*'VIP Levels'!$E$14+'Affiliate Projection'!E19*IFERROR(SUMPRODUCT('VIP Levels'!$E$15:$E$18,Inputs!$B$35:$B$38)/SUM(Inputs!$B$35:$B$38),0),0) -> 26 | F6: =ROUND('Affiliate Projection'!F18*'VIP Levels'!$E$14+'Affiliate Projection'!F19*IFERROR(SUMPRODUCT('VIP Levels'!$E$15:$E$18,Inputs!$B$35:$B$38)/SUM(Inputs!$B$35:$B$38),0),0) -> 26 | G6: =ROUND('Affiliate Projection'!G18*'VIP Levels'!$E$14+'Affiliate Projection'!G19*IFERROR(SUMPRODUCT('VIP Levels'!$E$15:$E$18,Inputs!$B$35:$B$38)/SUM(Inputs!$B$35:$B$38),0),0) -> 24 | H6: =ROUND('Affiliate Projection'!H18*'VIP Levels'!$E$14+'Affiliate Projection'!H19*IFERROR(SUMPRODUCT('VIP Levels'!$E$15:$E$18,Inputs!$B$35:$B$38)/SUM(Inputs!$B$35:$B$38),0),0) -> 23 | I6: =ROUND('Affiliate Projection'!I18*'VIP Levels'!$E$14+'Affiliate Projection'!I19*IFERROR(SUMPRODUCT('VIP Levels'!$E$15:$E$18,Inputs!$B$35:$B$38)/SUM(Inputs!$B$35:$B$38),0),0) -> 22 | ... M6: =ROUND('Affiliate Projection'!M18*'VIP Levels'!$E$14+'Affiliate Projection'!M19*IFERROR(SUMPRODUCT('VIP Levels'!$E$15:$E$18,Inputs!$B$35:$B$38)/SUM(Inputs!$B$35:$B$38),0),0) -> 18
A7: Discount Coupons Triggered | B7: =ROUND('Affiliate Projection'!B18*'VIP Levels'!$G$14+'Affiliate Projection'!B19*IFERROR(SUMPRODUCT('VIP Levels'!$G$15:$G$18,Inputs!$B$35:$B$38)/SUM(Inputs!$B$35:$B$38),0),0) -> 230 | C7: =ROUND('Affiliate Projection'!C18*'VIP Levels'!$G$14+'Affiliate Projection'!C19*IFERROR(SUMPRODUCT('VIP Levels'!$G$15:$G$18,Inputs!$B$35:$B$38)/SUM(Inputs!$B$35:$B$38),0),0) -> 301 | D7: =ROUND('Affiliate Projection'!D18*'VIP Levels'!$G$14+'Affiliate Projection'!D19*IFERROR(SUMPRODUCT('VIP Levels'!$G$15:$G$18,Inputs!$B$35:$B$38)/SUM(Inputs!$B$35:$B$38),0),0) -> 214 | E7: =ROUND('Affiliate Projection'!E18*'VIP Levels'!$G$14+'Affiliate Projection'!E19*IFERROR(SUMPRODUCT('VIP Levels'!$G$15:$G$18,Inputs!$B$35:$B$38)/SUM(Inputs!$B$35:$B$38),0),0) -> 209 | F7: =ROUND('Affiliate Projection'!F18*'VIP Levels'!$G$14+'Affiliate Projection'!F19*IFERROR(SUMPRODUCT('VIP Levels'!$G$15:$G$18,Inputs!$B$35:$B$38)/SUM(Inputs!$B$35:$B$38),0),0) -> 209 | G7: =ROUND('Affiliate Projection'!G18*'VIP Levels'!$G$14+'Affiliate Projection'!G19*IFERROR(SUMPRODUCT('VIP Levels'!$G$15:$G$18,Inputs!$B$35:$B$38)/SUM(Inputs!$B$35:$B$38),0),0) -> 205 | H7: =ROUND('Affiliate Projection'!H18*'VIP Levels'!$G$14+'Affiliate Projection'!H19*IFERROR(SUMPRODUCT('VIP Levels'!$G$15:$G$18,Inputs!$B$35:$B$38)/SUM(Inputs!$B$35:$B$38),0),0) -> 203 | I7: =ROUND('Affiliate Projection'!I18*'VIP Levels'!$G$14+'Affiliate Projection'!I19*IFERROR(SUMPRODUCT('VIP Levels'!$G$15:$G$18,Inputs!$B$35:$B$38)/SUM(Inputs!$B$35:$B$38),0),0) -> 201 | ... M7: =ROUND('Affiliate Projection'!M18*'VIP Levels'!$G$14+'Affiliate Projection'!M19*IFERROR(SUMPRODUCT('VIP Levels'!$G$15:$G$18,Inputs!$B$35:$B$38)/SUM(Inputs!$B$35:$B$38),0),0) -> 194
A8: Spark Ads Triggered | B8: =ROUND('Affiliate Projection'!B18*'VIP Levels'!$I$14+'Affiliate Projection'!B19*IFERROR(SUMPRODUCT('VIP Levels'!$I$15:$I$18,Inputs!$B$35:$B$38)/SUM(Inputs!$B$35:$B$38),0),0) -> 0 | C8: =ROUND('Affiliate Projection'!C18*'VIP Levels'!$I$14+'Affiliate Projection'!C19*IFERROR(SUMPRODUCT('VIP Levels'!$I$15:$I$18,Inputs!$B$35:$B$38)/SUM(Inputs!$B$35:$B$38),0),0) -> 75 | D8: =ROUND('Affiliate Projection'!D18*'VIP Levels'!$I$14+'Affiliate Projection'!D19*IFERROR(SUMPRODUCT('VIP Levels'!$I$15:$I$18,Inputs!$B$35:$B$38)/SUM(Inputs!$B$35:$B$38),0),0) -> 29 | E8: =ROUND('Affiliate Projection'!E18*'VIP Levels'!$I$14+'Affiliate Projection'!E19*IFERROR(SUMPRODUCT('VIP Levels'!$I$15:$I$18,Inputs!$B$35:$B$38)/SUM(Inputs!$B$35:$B$38),0),0) -> 26 | F8: =ROUND('Affiliate Projection'!F18*'VIP Levels'!$I$14+'Affiliate Projection'!F19*IFERROR(SUMPRODUCT('VIP Levels'!$I$15:$I$18,Inputs!$B$35:$B$38)/SUM(Inputs!$B$35:$B$38),0),0) -> 26 | G8: =ROUND('Affiliate Projection'!G18*'VIP Levels'!$I$14+'Affiliate Projection'!G19*IFERROR(SUMPRODUCT('VIP Levels'!$I$15:$I$18,Inputs!$B$35:$B$38)/SUM(Inputs!$B$35:$B$38),0),0) -> 24 | H8: =ROUND('Affiliate Projection'!H18*'VIP Levels'!$I$14+'Affiliate Projection'!H19*IFERROR(SUMPRODUCT('VIP Levels'!$I$15:$I$18,Inputs!$B$35:$B$38)/SUM(Inputs!$B$35:$B$38),0),0) -> 23 | I8: =ROUND('Affiliate Projection'!I18*'VIP Levels'!$I$14+'Affiliate Projection'!I19*IFERROR(SUMPRODUCT('VIP Levels'!$I$15:$I$18,Inputs!$B$35:$B$38)/SUM(Inputs!$B$35:$B$38),0),0) -> 22 | ... M8: =ROUND('Affiliate Projection'!M18*'VIP Levels'!$I$14+'Affiliate Projection'!M19*IFERROR(SUMPRODUCT('VIP Levels'!$I$15:$I$18,Inputs!$B$35:$B$38)/SUM(Inputs!$B$35:$B$38),0),0) -> 18
A9: Physical Gifts Triggered | B9: =ROUND('Affiliate Projection'!B18*'VIP Levels'!$K$14+'Affiliate Projection'!B19*IFERROR(SUMPRODUCT('VIP Levels'!$K$15:$K$18,Inputs!$B$35:$B$38)/SUM(Inputs!$B$35:$B$38),0),0) -> 0 | C9: =ROUND('Affiliate Projection'!C18*'VIP Levels'!$K$14+'Affiliate Projection'!C19*IFERROR(SUMPRODUCT('VIP Levels'!$K$15:$K$18,Inputs!$B$35:$B$38)/SUM(Inputs!$B$35:$B$38),0),0) -> 28 | D9: =ROUND('Affiliate Projection'!D18*'VIP Levels'!$K$14+'Affiliate Projection'!D19*IFERROR(SUMPRODUCT('VIP Levels'!$K$15:$K$18,Inputs!$B$35:$B$38)/SUM(Inputs!$B$35:$B$38),0),0) -> 11 | E9: =ROUND('Affiliate Projection'!E18*'VIP Levels'!$K$14+'Affiliate Projection'!E19*IFERROR(SUMPRODUCT('VIP Levels'!$K$15:$K$18,Inputs!$B$35:$B$38)/SUM(Inputs!$B$35:$B$38),0),0) -> 10 | F9: =ROUND('Affiliate Projection'!F18*'VIP Levels'!$K$14+'Affiliate Projection'!F19*IFERROR(SUMPRODUCT('VIP Levels'!$K$15:$K$18,Inputs!$B$35:$B$38)/SUM(Inputs!$B$35:$B$38),0),0) -> 10 | G9: =ROUND('Affiliate Projection'!G18*'VIP Levels'!$K$14+'Affiliate Projection'!G19*IFERROR(SUMPRODUCT('VIP Levels'!$K$15:$K$18,Inputs!$B$35:$B$38)/SUM(Inputs!$B$35:$B$38),0),0) -> 9 | H9: =ROUND('Affiliate Projection'!H18*'VIP Levels'!$K$14+'Affiliate Projection'!H19*IFERROR(SUMPRODUCT('VIP Levels'!$K$15:$K$18,Inputs!$B$35:$B$38)/SUM(Inputs!$B$35:$B$38),0),0) -> 9 | I9: =ROUND('Affiliate Projection'!I18*'VIP Levels'!$K$14+'Affiliate Projection'!I19*IFERROR(SUMPRODUCT('VIP Levels'!$K$15:$K$18,Inputs!$B$35:$B$38)/SUM(Inputs!$B$35:$B$38),0),0) -> 8 | ... M9: =ROUND('Affiliate Projection'!M18*'VIP Levels'!$K$14+'Affiliate Projection'!M19*IFERROR(SUMPRODUCT('VIP Levels'!$K$15:$K$18,Inputs!$B$35:$B$38)/SUM(Inputs!$B$35:$B$38),0),0) -> 7
A10: Experiences Triggered | B10: =ROUND('Affiliate Projection'!B18*'VIP Levels'!$M$14+'Affiliate Projection'!B19*IFERROR(SUMPRODUCT('VIP Levels'!$M$15:$M$18,Inputs!$B$35:$B$38)/SUM(Inputs!$B$35:$B$38),0),0) -> 0 | C10: =ROUND('Affiliate Projection'!C18*'VIP Levels'!$M$14+'Affiliate Projection'!C19*IFERROR(SUMPRODUCT('VIP Levels'!$M$15:$M$18,Inputs!$B$35:$B$38)/SUM(Inputs!$B$35:$B$38),0),0) -> 9 | D10: =ROUND('Affiliate Projection'!D18*'VIP Levels'!$M$14+'Affiliate Projection'!D19*IFERROR(SUMPRODUCT('VIP Levels'!$M$15:$M$18,Inputs!$B$35:$B$38)/SUM(Inputs!$B$35:$B$38),0),0) -> 4 | E10: =ROUND('Affiliate Projection'!E18*'VIP Levels'!$M$14+'Affiliate Projection'!E19*IFERROR(SUMPRODUCT('VIP Levels'!$M$15:$M$18,Inputs!$B$35:$B$38)/SUM(Inputs!$B$35:$B$38),0),0) -> 3 | F10: =ROUND('Affiliate Projection'!F18*'VIP Levels'!$M$14+'Affiliate Projection'!F19*IFERROR(SUMPRODUCT('VIP Levels'!$M$15:$M$18,Inputs!$B$35:$B$38)/SUM(Inputs!$B$35:$B$38),0),0) -> 3 | G10: =ROUND('Affiliate Projection'!G18*'VIP Levels'!$M$14+'Affiliate Projection'!G19*IFERROR(SUMPRODUCT('VIP Levels'!$M$15:$M$18,Inputs!$B$35:$B$38)/SUM(Inputs!$B$35:$B$38),0),0) -> 3 | H10: =ROUND('Affiliate Projection'!H18*'VIP Levels'!$M$14+'Affiliate Projection'!H19*IFERROR(SUMPRODUCT('VIP Levels'!$M$15:$M$18,Inputs!$B$35:$B$38)/SUM(Inputs!$B$35:$B$38),0),0) -> 3 | I10: =ROUND('Affiliate Projection'!I18*'VIP Levels'!$M$14+'Affiliate Projection'!I19*IFERROR(SUMPRODUCT('VIP Levels'!$M$15:$M$18,Inputs!$B$35:$B$38)/SUM(Inputs!$B$35:$B$38),0),0) -> 3 | ... M10: =ROUND('Affiliate Projection'!M18*'VIP Levels'!$M$14+'Affiliate Projection'!M19*IFERROR(SUMPRODUCT('VIP Levels'!$M$15:$M$18,Inputs!$B$35:$B$38)/SUM(Inputs!$B$35:$B$38),0),0) -> 2
A12: --- MISSION COMPLETIONS ---
A13: Mission Completions (Bronze) | B13: =ROUND('Affiliate Projection'!B12*Missions!$B$31*Missions!$C$31,0) -> 196 | C13: =ROUND('Affiliate Projection'!C12*Missions!$B$31*Missions!$C$31,0) -> 209 | D13: =ROUND('Affiliate Projection'!D12*Missions!$B$31*Missions!$C$31,0) -> 287 | E13: =ROUND('Affiliate Projection'!E12*Missions!$B$31*Missions!$C$31,0) -> 362 | F13: =ROUND('Affiliate Projection'!F12*Missions!$B$31*Missions!$C$31,0) -> 432 | G13: =ROUND('Affiliate Projection'!G12*Missions!$B$31*Missions!$C$31,0) -> 498 | H13: =ROUND('Affiliate Projection'!H12*Missions!$B$31*Missions!$C$31,0) -> 561 | I13: =ROUND('Affiliate Projection'!I12*Missions!$B$31*Missions!$C$31,0) -> 622 | ... M13: =ROUND('Affiliate Projection'!M12*Missions!$B$31*Missions!$C$31,0) -> 835
A14: Mission Completions (Silver) | B14: =ROUND('Affiliate Projection'!B13*Missions!$B$32*Missions!$C$32,0) -> 0 | C14: =ROUND('Affiliate Projection'!C13*Missions!$B$32*Missions!$C$32,0) -> 76 | D14: =ROUND('Affiliate Projection'!D13*Missions!$B$32*Missions!$C$32,0) -> 104 | E14: =ROUND('Affiliate Projection'!E13*Missions!$B$32*Missions!$C$32,0) -> 130 | F14: =ROUND('Affiliate Projection'!F13*Missions!$B$32*Missions!$C$32,0) -> 156 | G14: =ROUND('Affiliate Projection'!G13*Missions!$B$32*Missions!$C$32,0) -> 180 | H14: =ROUND('Affiliate Projection'!H13*Missions!$B$32*Missions!$C$32,0) -> 204 | I14: =ROUND('Affiliate Projection'!I13*Missions!$B$32*Missions!$C$32,0) -> 226 | ... M14: =ROUND('Affiliate Projection'!M13*Missions!$B$32*Missions!$C$32,0) -> 302
A15: Mission Completions (Gold) | B15: =ROUND('Affiliate Projection'!B14*Missions!$B$33*Missions!$C$33,0) -> 0 | C15: =ROUND('Affiliate Projection'!C14*Missions!$B$33*Missions!$C$33,0) -> 36 | D15: =ROUND('Affiliate Projection'!D14*Missions!$B$33*Missions!$C$33,0) -> 49 | E15: =ROUND('Affiliate Projection'!E14*Missions!$B$33*Missions!$C$33,0) -> 63 | F15: =ROUND('Affiliate Projection'!F14*Missions!$B$33*Missions!$C$33,0) -> 74 | G15: =ROUND('Affiliate Projection'!G14*Missions!$B$33*Missions!$C$33,0) -> 86 | H15: =ROUND('Affiliate Projection'!H14*Missions!$B$33*Missions!$C$33,0) -> 97 | I15: =ROUND('Affiliate Projection'!I14*Missions!$B$33*Missions!$C$33,0) -> 106 | ... M15: =ROUND('Affiliate Projection'!M14*Missions!$B$33*Missions!$C$33,0) -> 144
A16: Mission Completions (Platinum) | B16: =ROUND('Affiliate Projection'!B15*Missions!$B$34*Missions!$C$34,0) -> 0 | C16: =ROUND('Affiliate Projection'!C15*Missions!$B$34*Missions!$C$34,0) -> 14 | D16: =ROUND('Affiliate Projection'!D15*Missions!$B$34*Missions!$C$34,0) -> 21 | E16: =ROUND('Affiliate Projection'!E15*Missions!$B$34*Missions!$C$34,0) -> 26 | F16: =ROUND('Affiliate Projection'!F15*Missions!$B$34*Missions!$C$34,0) -> 32 | G16: =ROUND('Affiliate Projection'!G15*Missions!$B$34*Missions!$C$34,0) -> 37 | H16: =ROUND('Affiliate Projection'!H15*Missions!$B$34*Missions!$C$34,0) -> 40 | I16: =ROUND('Affiliate Projection'!I15*Missions!$B$34*Missions!$C$34,0) -> 45 | ... M16: =ROUND('Affiliate Projection'!M15*Missions!$B$34*Missions!$C$34,0) -> 61
A17: Mission Completions (Diamond) | B17: =ROUND('Affiliate Projection'!B16*Missions!$B$35*Missions!$C$35,0) -> 0 | C17: =ROUND('Affiliate Projection'!C16*Missions!$B$35*Missions!$C$35,0) -> 0 | D17: =ROUND('Affiliate Projection'!D16*Missions!$B$35*Missions!$C$35,0) -> 0 | E17: =ROUND('Affiliate Projection'!E16*Missions!$B$35*Missions!$C$35,0) -> 0 | F17: =ROUND('Affiliate Projection'!F16*Missions!$B$35*Missions!$C$35,0) -> 0 | G17: =ROUND('Affiliate Projection'!G16*Missions!$B$35*Missions!$C$35,0) -> 0 | H17: =ROUND('Affiliate Projection'!H16*Missions!$B$35*Missions!$C$35,0) -> 0 | I17: =ROUND('Affiliate Projection'!I16*Missions!$B$35*Missions!$C$35,0) -> 0 | ... M17: =ROUND('Affiliate Projection'!M16*Missions!$B$35*Missions!$C$35,0) -> 0
A18: Total Mission Completions | B18: =SUM(B13:B17) -> 196 | C18: =SUM(C13:C17) -> 335 | D18: =SUM(D13:D17) -> 461 | E18: =SUM(E13:E17) -> 581 | F18: =SUM(F13:F17) -> 694 | G18: =SUM(G13:G17) -> 801 | H18: =SUM(H13:H17) -> 902 | I18: =SUM(I13:I17) -> 999 | ... M18: =SUM(M13:M17) -> 1342

Sheet Revenue
A1: REVENUE PROJECTION (12 MONTHS)
A3: Metric | B3: Month 1 | C3: Month 2 | D3: Month 3 | E3: Month 4 | F3: Month 5 | G3: Month 6 | H3: Month 7 | I3: Month 8 | J3: Month 9 | K3: Month 10 | L3: Month 11 | M3: Month 12
A4: Total Sales Volume | B4: ='Affiliate Projection'!B10 -> 230 | C4: ='Affiliate Projection'!C10 -> 927 | D4: ='Affiliate Projection'!D10 -> 1287 | E4: ='Affiliate Projection'!E10 -> 1612 | F4: ='Affiliate Projection'!F10 -> 1944 | G4: ='Affiliate Projection'!G10 -> 2241 | H4: ='Affiliate Projection'!H10 -> 2509 | I4: ='Affiliate Projection'!I10 -> 2782 | ... M4: ='Affiliate Projection'!M10 -> 3750
A5: Gross AOV | B5: =Inputs!$B$15 -> 100 | C5: =Inputs!$B$15 -> 100 | D5: =Inputs!$B$15 -> 100 | E5: =Inputs!$B$15 -> 100 | F5: =Inputs!$B$15 -> 100 | G5: =Inputs!$B$15 -> 100 | H5: =Inputs!$B$15 -> 100 | I5: =Inputs!$B$15 -> 100 | ... M5: =Inputs!$B$15 -> 100
A6: Gross Revenue | B6: =B4*B5 -> 23000 | C6: =C4*C5 -> 92700 | D6: =D4*D5 -> 128700 | E6: =E4*E5 -> 161200 | F6: =F4*F5 -> 194400 | G6: =G4*G5 -> 224100 | H6: =H4*H5 -> 250900 | I6: =I4*I5 -> 278200 | ... M6: =M4*M5 -> 375000
A7: Avg Discount % (when redeemed) | B7: =SUMPRODUCT('VIP Levels'!$H$14:$H$18,Inputs!$B$34:$B$38) -> 0.16 | C7: =SUMPRODUCT('VIP Levels'!$H$14:$H$18,Inputs!$B$34:$B$38) -> 0.16 | D7: =SUMPRODUCT('VIP Levels'!$H$14:$H$18,Inputs!$B$34:$B$38) -> 0.16 | E7: =SUMPRODUCT('VIP Levels'!$H$14:$H$18,Inputs!$B$34:$B$38) -> 0.16 | F7: =SUMPRODUCT('VIP Levels'!$H$14:$H$18,Inputs!$B$34:$B$38) -> 0.16 | G7: =SUMPRODUCT('VIP Levels'!$H$14:$H$18,Inputs!$B$34:$B$38) -> 0.16 | H7: =SUMPRODUCT('VIP Levels'!$H$14:$H$18,Inputs!$B$34:$B$38) -> 0.16 | I7: =SUMPRODUCT('VIP Levels'!$H$14:$H$18,Inputs!$B$34:$B$38) -> 0.16 | ... M7: =SUMPRODUCT('VIP Levels'!$H$14:$H$18,Inputs!$B$34:$B$38) -> 0.16
A8: Discount Redemption Rate | B8: =Inputs!$B$21 -> 0.3 | C8: =Inputs!$B$21 -> 0.3 | D8: =Inputs!$B$21 -> 0.3 | E8: =Inputs!$B$21 -> 0.3 | F8: =Inputs!$B$21 -> 0.3 | G8: =Inputs!$B$21 -> 0.3 | H8: =Inputs!$B$21 -> 0.3 | I8: =Inputs!$B$21 -> 0.3 | ... M8: =Inputs!$B$21 -> 0.3
A9: Discounted Sales Count | B9: =ROUND(B4*B8,0) -> 69 | C9: =ROUND(C4*C8,0) -> 278 | D9: =ROUND(D4*D8,0) -> 386 | E9: =ROUND(E4*E8,0) -> 484 | F9: =ROUND(F4*F8,0) -> 583 | G9: =ROUND(G4*G8,0) -> 672 | H9: =ROUND(H4*H8,0) -> 753 | I9: =ROUND(I4*I8,0) -> 835 | ... M9: =ROUND(M4*M8,0) -> 1125
A10: Net AOV (weighted avg) | B10: =B5*(1-B7*B8) -> 95.2 | C10: =C5*(1-C7*C8) -> 95.2 | D10: =D5*(1-D7*D8) -> 95.2 | E10: =E5*(1-E7*E8) -> 95.2 | F10: =F5*(1-F7*F8) -> 95.2 | G10: =G5*(1-G7*G8) -> 95.2 | H10: =H5*(1-H7*H8) -> 95.2 | I10: =I5*(1-I7*I8) -> 95.2 | ... M10: =M5*(1-M7*M8) -> 95.2
A11: Net Revenue | B11: =B4*B10 -> 21896 | C11: =C4*C10 -> 88250.4 | D11: =D4*D10 -> 122522.4 | E11: =E4*E10 -> 153462.4 | F11: =F4*F10 -> 185068.8 | G11: =G4*G10 -> 213343.2 | H11: =H4*H10 -> 238856.8 | I11: =I4*I10 -> 264846.4 | ... M11: =M4*M10 -> 357000
A12: Discount Margin Erosion | B12: =B6-B11 -> 1104 | C12: =C6-C11 -> 4449.6 | D12: =D6-D11 -> 6177.6 | E12: =E6-E11 -> 7737.6 | F12: =F6-F11 -> 9331.2 | G12: =G6-G11 -> 10756.8 | H12: =H6-H11 -> 12043.2 | I12: =I6-I11 -> 13353.6 | ... M12: =M6-M11 -> 18000

Sheet Costs
A1: COST PROJECTION (12 MONTHS)
A3: Metric | B3: Month 1 | C3: Month 2 | D3: Month 3 | E3: Month 4 | F3: Month 5 | G3: Month 6 | H3: Month 7 | I3: Month 8 | J3: Month 9 | K3: Month 10 | L3: Month 11 | M3: Month 12
A4: --- CM1 COSTS (Per Sale) ---
A5: Base Commission Cost | B5: ='Affiliate Projection'!B10*SUMPRODUCT('VIP Levels'!$D$5:$D$9,Inputs!$B$34:$B$38)*Revenue!B10 -> 2583.728 | C5: ='Affiliate Projection'!C10*SUMPRODUCT('VIP Levels'!$D$5:$D$9,Inputs!$B$34:$B$38)*Revenue!C10 -> 10413.547 | D5: ='Affiliate Projection'!D10*SUMPRODUCT('VIP Levels'!$D$5:$D$9,Inputs!$B$34:$B$38)*Revenue!D10 -> 14457.643 | E5: ='Affiliate Projection'!E10*SUMPRODUCT('VIP Levels'!$D$5:$D$9,Inputs!$B$34:$B$38)*Revenue!E10 -> 18108.563 | F5: ='Affiliate Projection'!F10*SUMPRODUCT('VIP Levels'!$D$5:$D$9,Inputs!$B$34:$B$38)*Revenue!F10 -> 21838.118 | G5: ='Affiliate Projection'!G10*SUMPRODUCT('VIP Levels'!$D$5:$D$9,Inputs!$B$34:$B$38)*Revenue!G10 -> 25174.498 | H5: ='Affiliate Projection'!H10*SUMPRODUCT('VIP Levels'!$D$5:$D$9,Inputs!$B$34:$B$38)*Revenue!H10 -> 28185.102 | I5: ='Affiliate Projection'!I10*SUMPRODUCT('VIP Levels'!$D$5:$D$9,Inputs!$B$34:$B$38)*Revenue!I10 -> 31251.875 | ... M5: ='Affiliate Projection'!M10*SUMPRODUCT('VIP Levels'!$D$5:$D$9,Inputs!$B$34:$B$38)*Revenue!M10 -> 42126
A6: Commission Boost Cost (Welcome) | B6: ='Reward Triggers'!B5*SUMPRODUCT('VIP Levels'!$E$5:$E$9,Inputs!$B$34:$B$38)*'VIP Levels'!$B$22*Revenue!B10 -> 6909.5565 | C6: ='Reward Triggers'!C5*SUMPRODUCT('VIP Levels'!$E$5:$E$9,Inputs!$B$34:$B$38)*'VIP Levels'!$B$22*Revenue!C10 -> 11596.038 | D6: ='Reward Triggers'!D5*SUMPRODUCT('VIP Levels'!$E$5:$E$9,Inputs!$B$34:$B$38)*'VIP Levels'!$B$22*Revenue!D10 -> 7390.2213 | E6: ='Reward Triggers'!E5*SUMPRODUCT('VIP Levels'!$E$5:$E$9,Inputs!$B$34:$B$38)*'VIP Levels'!$B$22*Revenue!E10 -> 7149.8889 | F6: ='Reward Triggers'!F5*SUMPRODUCT('VIP Levels'!$E$5:$E$9,Inputs!$B$34:$B$38)*'VIP Levels'!$B$22*Revenue!F10 -> 7149.8889 | G6: ='Reward Triggers'!G5*SUMPRODUCT('VIP Levels'!$E$5:$E$9,Inputs!$B$34:$B$38)*'VIP Levels'!$B$22*Revenue!G10 -> 6969.6396 | H6: ='Reward Triggers'!H5*SUMPRODUCT('VIP Levels'!$E$5:$E$9,Inputs!$B$34:$B$38)*'VIP Levels'!$B$22*Revenue!H10 -> 6849.4734 | I6: ='Reward Triggers'!I5*SUMPRODUCT('VIP Levels'!$E$5:$E$9,Inputs!$B$34:$B$38)*'VIP Levels'!$B$22*Revenue!I10 -> 6789.3903 | ... M6: ='Reward Triggers'!M5*SUMPRODUCT('VIP Levels'!$E$5:$E$9,Inputs!$B$34:$B$38)*'VIP Levels'!$B$22*Revenue!M10 -> 6428.8917
A7: Commission Boost Cost (Missions) | B7: =SUMPRODUCT((Missions!$F$6:$F$26="Commission Boost")*(Missions!$A$6:$A$26="Bronze")*'Affiliate Projection'!B12*Missions!$E$6:$E$26*Missions!$J$6:$J$26)+SUMPRODUCT((Missions!$F$6:$F$26="Commission Boost")*(Missions!$A$6:$A$26="Silver")*'Affiliate Projection'!B13*Missions!$E$6:$E$26*Missions!$J$6:$J$26)+SUMPRODUCT((Missions!$F$6:$F$26="Commission Boost")*(Missions!$A$6:$A$26="Gold")*'Affiliate Projection'!B14*Missions!$E$6:$E$26*Missions!$J$6:$J$26)+SUMPRODUCT((Missions!$F$6:$F$26="Commission Boost")*(Missions!$A$6:$A$26="Platinum")*'Affiliate Projection'!B15*Missions!$E$6:$E$26*Missions!$J$6:$J$26)+SUMPRODUCT((Missions!$F$6:$F$26="Commission Boost")*(Missions!$A$6:$A$26="Diamond")*'Affiliate Projection'!B16*Missions!$E$6:$E$26*Missions!$J$6:$J$26) -> 0 | C7: =SUMPRODUCT((Missions!$F$6:$F$26="Commission Boost")*(Missions!$A$6:$A$26="Bronze")*'Affiliate Projection'!C12*Missions!$E$6:$E$26*Missions!$J$6:$J$26)+SUMPRODUCT((Missions!$F$6:$F$26="Commission Boost")*(Missions!$A$6:$A$26="Silver")*'Affiliate Projection'!C13*Missions!$E$6:$E$26*Missions!$J$6:$J$26)+SUMPRODUCT((Missions!$F$6:$F$26="Commission Boost")*(Missions!$A$6:$A$26="Gold")*'Affiliate Projection'!C14*Missions!$E$6:$E$26*Missions!$J$6:$J$26)+SUMPRODUCT((Missions!$F$6:$F$26="Commission Boost")*(Missions!$A$6:$A$26="Platinum")*'Affiliate Projection'!C15*Missions!$E$6:$E$26*Missions!$J$6:$J$26)+SUMPRODUCT((Missions!$F$6:$F$26="Commission Boost")*(Missions!$A$6:$A$26="Diamond")*'Affiliate Projection'!C16*Missions!$E$6:$E$26*Missions!$J$6:$J$26) -> 1183.1932 | D7: =SUMPRODUCT((Missions!$F$6:$F$26="Commission Boost")*(Missions!$A$6:$A$26="Bronze")*'Affiliate Projection'!D12*Missions!$E$6:$E$26*Missions!$J$6:$J$26)+SUMPRODUCT((Missions!$F$6:$F$26="Commission Boost")*(Missions!$A$6:$A$26="Silver")*'Affiliate Projection'!D13*Missions!$E$6:$E$26*Missions!$J$6:$J$26)+SUMPRODUCT((Missions!$F$6:$F$26="Commission Boost")*(Missions!$A$6:$A$26="Gold")*'Affiliate Projection'!D14*Missions!$E$6:$E$26*Missions!$J$6:$J$26)+SUMPRODUCT((Missions!$F$6:$F$26="Commission Boost")*(Missions!$A$6:$A$26="Platinum")*'Affiliate Projection'!D15*Missions!$E$6:$E$26*Missions!$J$6:$J$26)+SUMPRODUCT((Missions!$F$6:$F$26="Commission Boost")*(Missions!$A$6:$A$26="Diamond")*'Affiliate Projection'!D16*Missions!$E$6:$E$26*Missions!$J$6:$J$26) -> 1659.0028 | E7: =SUMPRODUCT((Missions!$F$6:$F$26="Commission Boost")*(Missions!$A$6:$A$26="Bronze")*'Affiliate Projection'!E12*Missions!$E$6:$E$26*Missions!$J$6:$J$26)+SUMPRODUCT((Missions!$F$6:$F$26="Commission Boost")*(Missions!$A$6:$A$26="Silver")*'Affiliate Projection'!E13*Missions!$E$6:$E$26*Missions!$J$6:$J$26)+SUMPRODUCT((Missions!$F$6:$F$26="Commission Boost")*(Missions!$A$6:$A$26="Gold")*'Affiliate Projection'!E14*Missions!$E$6:$E$26*Missions!$J$6:$J$26)+SUMPRODUCT((Missions!$F$6:$F$26="Commission Boost")*(Missions!$A$6:$A$26="Platinum")*'Affiliate Projection'!E15*Missions!$E$6:$E$26*Missions!$J$6:$J$26)+SUMPRODUCT((Missions!$F$6:$F$26="Commission Boost")*(Missions!$A$6:$A$26="Diamond")*'Affiliate Projection'!E16*Missions!$E$6:$E$26*Missions!$J$6:$J$26) -> 2068.5056 | F7: =SUMPRODUCT((Missions!$F$6:$F$26="Commission Boost")*(Missions!$A$6:$A$26="Bronze")*'Affiliate Projection'!F12*Missions!$E$6:$E$26*Missions!$J$6:$J$26)+SUMPRODUCT((Missions!$F$6:$F$26="Commission Boost")*(Missions!$A$6:$A$26="Silver")*'Affiliate Projection'!F13*Missions!$E$6:$E$26*Missions!$J$6:$J$26)+SUMPRODUCT((Missions!$F$6:$F$26="Commission Boost")*(Missions!$A$6:$A$26="Gold")*'Affiliate Projection'!F14*Missions!$E$6:$E$26*Missions!$J$6:$J$26)+SUMPRODUCT((Missions!$F$6:$F$26="Commission Boost")*(Missions!$A$6:$A$26="Platinum")*'Affiliate Projection'!F15*Missions!$E$6:$E$26*Missions!$J$6:$J$26)+SUMPRODUCT((Missions!$F$6:$F$26="Commission Boost")*(Missions!$A$6:$A$26="Diamond")*'Affiliate Projection'!F16*Missions!$E$6:$E$26*Missions!$J$6:$J$26) -> 2517.6592 | G7: =SUMPRODUCT((Missions!$F$6:$F$26="Commission Boost")*(Missions!$A$6:$A$26="Bronze")*'Affiliate Projection'!G12*Missions!$E$6:$E$26*Missions!$J$6:$J$26)+SUMPRODUCT((Missions!$F$6:$F$26="Commission Boost")*(Missions!$A$6:$A$26="Silver")*'Affiliate Projection'!G13*Missions!$E$6:$E$26*Missions!$J$6:$J$26)+SUMPRODUCT((Missions!$F$6:$F$26="Commission Boost")*(Missions!$A$6:$A$26="Gold")*'Affiliate Projection'!G14*Missions!$E$6:$E$26*Missions!$J$6:$J$26)+SUMPRODUCT((Missions!$F$6:$F$26="Commission Boost")*(Missions!$A$6:$A$26="Platinum")*'Affiliate Projection'!G15*Missions!$E$6:$E$26*Missions!$J$6:$J$26)+SUMPRODUCT((Missions!$F$6:$F$26="Commission Boost")*(Missions!$A$6:$A$26="Diamond")*'Affiliate Projection'!G16*Missions!$E$6:$E$26*Missions!$J$6:$J$26) -> 2900.506 | H7: =SUMPRODUCT((Missions!$F$6:$F$26="Commission Boost")*(Missions!$A$6:$A$26="Bronze")*'Affiliate Projection'!H12*Missions!$E$6:$E$26*Missions!$J$6:$J$26)+SUMPRODUCT((Missions!$F$6:$F$26="Commission Boost")*(Missions!$A$6:$A$26="Silver")*'Affiliate Projection'!H13*Missions!$E$6:$E$26*Missions!$J$6:$J$26)+SUMPRODUCT((Missions!$F$6:$F$26="Commission Boost")*(Missions!$A$6:$A$26="Gold")*'Affiliate Projection'!H14*Missions!$E$6:$E$26*Missions!$J$6:$J$26)+SUMPRODUCT((Missions!$F$6:$F$26="Commission Boost")*(Missions!$A$6:$A$26="Platinum")*'Affiliate Projection'!H15*Missions!$E$6:$E$26*Missions!$J$6:$J$26)+SUMPRODUCT((Missions!$F$6:$F$26="Commission Boost")*(Missions!$A$6:$A$26="Diamond")*'Affiliate Projection'!H16*Missions!$E$6:$E$26*Missions!$J$6:$J$26) -> 3225.0428 | I7: =SUMPRODUCT((Missions!$F$6:$F$26="Commission Boost")*(Missions!$A$6:$A$26="Bronze")*'Affiliate Projection'!I12*Missions!$E$6:$E$26*Missions!$J$6:$J$26)+SUMPRODUCT((Missions!$F$6:$F$26="Commission Boost")*(Missions!$A$6:$A$26="Silver")*'Affiliate Projection'!I13*Missions!$E$6:$E$26*Missions!$J$6:$J$26)+SUMPRODUCT((Missions!$F$6:$F$26="Commission Boost")*(Missions!$A$6:$A$26="Gold")*'Affiliate Projection'!I14*Missions!$E$6:$E$26*Missions!$J$6:$J$26)+SUMPRODUCT((Missions!$F$6:$F$26="Commission Boost")*(Missions!$A$6:$A$26="Platinum")*'Affiliate Projection'!I15*Missions!$E$6:$E$26*Missions!$J$6:$J$26)+SUMPRODUCT((Missions!$F$6:$F$26="Commission Boost")*(Missions!$A$6:$A$26="Diamond")*'Affiliate Projection'!I16*Missions!$E$6:$E$26*Missions!$J$6:$J$26) -> 3581.2336 | ... M7: =SUMPRODUCT((Missions!$F$6:$F$26="Commission Boost")*(Missions!$A$6:$A$26="Bronze")*'Affiliate Projection'!M12*Missions!$E$6:$E$26*Missions!$J$6:$J$26)+SUMPRODUCT((Missions!$F$6:$F$26="Commission Boost")*(Missions!$A$6:$A$26="Silver")*'Affiliate Projection'!M13*Missions!$E$6:$E$26*Missions!$J$6:$J$26)+SUMPRODUCT((Missions!$F$6:$F$26="Commission Boost")*(Missions!$A$6:$A$26="Gold")*'Affiliate Projection'!M14*Missions!$E$6:$E$26*Missions!$J$6:$J$26)+SUMPRODUCT((Missions!$F$6:$F$26="Commission Boost")*(Missions!$A$6:$A$26="Platinum")*'Affiliate Projection'!M15*Missions!$E$6:$E$26*Missions!$J$6:$J$26)+SUMPRODUCT((Missions!$F$6:$F$26="Commission Boost")*(Missions!$A$6:$A$26="Diamond")*'Affiliate Projection'!M16*Missions!$E$6:$E$26*Missions!$J$6:$J$26) -> 4841.396
A8: Discount Cost (Margin Erosion) | B8: =Revenue!B12 -> 1104 | C8: =Revenue!C12 -> 4449.6 | D8: =Revenue!D12 -> 6177.6 | E8: =Revenue!E12 -> 7737.6 | F8: =Revenue!F12 -> 9331.2 | G8: =Revenue!G12 -> 10756.8 | H8: =Revenue!H12 -> 12043.2 | I8: =Revenue!I12 -> 13353.6 | ... M8: =Revenue!M12 -> 18000
A9: Discount Cost (Missions) | B9: =SUMPRODUCT((Missions!$F$6:$F$26="Discount")*(Missions!$A$6:$A$26="Bronze")*'Affiliate Projection'!B12*Missions!$E$6:$E$26*Missions!$J$6:$J$26)+SUMPRODUCT((Missions!$F$6:$F$26="Discount")*(Missions!$A$6:$A$26="Silver")*'Affiliate Projection'!B13*Missions!$E$6:$E$26*Missions!$J$6:$J$26)+SUMPRODUCT((Missions!$F$6:$F$26="Discount")*(Missions!$A$6:$A$26="Gold")*'Affiliate Projection'!B14*Missions!$E$6:$E$26*Missions!$J$6:$J$26)+SUMPRODUCT((Missions!$F$6:$F$26="Discount")*(Missions!$A$6:$A$26="Platinum")*'Affiliate Projection'!B15*Missions!$E$6:$E$26*Missions!$J$6:$J$26)+SUMPRODUCT((Missions!$F$6:$F$26="Discount")*(Missions!$A$6:$A$26="Diamond")*'Affiliate Projection'!B16*Missions!$E$6:$E$26*Missions!$J$6:$J$26) -> 0 | C9: =SUMPRODUCT((Missions!$F$6:$F$26="Discount")*(Missions!$A$6:$A$26="Bronze")*'Affiliate Projection'!C12*Missions!$E$6:$E$26*Missions!$J$6:$J$26)+SUMPRODUCT((Missions!$F$6:$F$26="Discount")*(Missions!$A$6:$A$26="Silver")*'Affiliate Projection'!C13*Missions!$E$6:$E$26*Missions!$J$6:$J$26)+SUMPRODUCT((Missions!$F$6:$F$26="Discount")*(Missions!$A$6:$A$26="Gold")*'Affiliate Projection'!C14*Missions!$E$6:$E$26*Missions!$J$6:$J$26)+SUMPRODUCT((Missions!$F$6:$F$26="Discount")*(Missions!$A$6:$A$26="Platinum")*'Affiliate Projection'!C15*Missions!$E$6:$E$26*Missions!$J$6:$J$26)+SUMPRODUCT((Missions!$F$6:$F$26="Discount")*(Missions!$A$6:$A$26="Diamond")*'Affiliate Projection'!C16*Missions!$E$6:$E$26*Missions!$J$6:$J$26) -> 102.15 | D9: =SUMPRODUCT((Missions!$F$6:$F$26="Discount")*(Missions!$A$6:$A$26="Bronze")*'Affiliate Projection'!D12*Missions!$E$6:$E$26*Missions!$J$6:$J$26)+SUMPRODUCT((Missions!$F$6:$F$26="Discount")*(Missions!$A$6:$A$26="Silver")*'Affiliate Projection'!D13*Missions!$E$6:$E$26*Missions!$J$6:$J$26)+SUMPRODUCT((Missions!$F$6:$F$26="Discount")*(Missions!$A$6:$A$26="Gold")*'Affiliate Projection'!D14*Missions!$E$6:$E$26*Missions!$J$6:$J$26)+SUMPRODUCT((Missions!$F$6:$F$26="Discount")*(Missions!$A$6:$A$26="Platinum")*'Affiliate Projection'!D15*Missions!$E$6:$E$26*Missions!$J$6:$J$26)+SUMPRODUCT((Missions!$F$6:$F$26="Discount")*(Missions!$A$6:$A$26="Diamond")*'Affiliate Projection'!D16*Missions!$E$6:$E$26*Missions!$J$6:$J$26) -> 142.35 | E9: =SUMPRODUCT((Missions!$F$6:$F$26="Discount")*(Missions!$A$6:$A$26="Bronze")*'Affiliate Projection'!E12*Missions!$E$6:$E$26*Missions!$J$6:$J$26)+SUMPRODUCT((Missions!$F$6:$F$26="Discount")*(Missions!$A$6:$A$26="Silver")*'Affiliate Projection'!E13*Missions!$E$6:$E$26*Missions!$J$6:$J$26)+SUMPRODUCT((Missions!$F$6:$F$26="Discount")*(Missions!$A$6:$A$26="Gold")*'Affiliate Projection'!E14*Missions!$E$6:$E$26*Missions!$J$6:$J$26)+SUMPRODUCT((Missions!$F$6:$F$26="Discount")*(Missions!$A$6:$A$26="Platinum")*'Affiliate Projection'!E15*Missions!$E$6:$E$26*Missions!$J$6:$J$26)+SUMPRODUCT((Missions!$F$6:$F$26="Discount")*(Missions!$A$6:$A$26="Diamond")*'Affiliate Projection'!E16*Missions!$E$6:$E$26*Missions!$J$6:$J$26) -> 177.84 | F9: =SUMPRODUCT((Missions!$F$6:$F$26="Discount")*(Missions!$A$6:$A$26="Bronze")*'Affiliate Projection'!F12*Missions!$E$6:$E$26*Missions!$J$6:$J$26)+SUMPRODUCT((Missions!$F$6:$F$26="Discount")*(Missions!$A$6:$A$26="Silver")*'Affiliate Projection'!F13*Missions!$E$6:$E$26*Missions!$J$6:$J$26)+SUMPRODUCT((Missions!$F$6:$F$26="Discount")*(Missions!$A$6:$A$26="Gold")*'Affiliate Projection'!F14*Missions!$E$6:$E$26*Missions!$J$6:$J$26)+SUMPRODUCT((Missions!$F$6:$F$26="Discount")*(Missions!$A$6:$A$26="Platinum")*'Affiliate Projection'!F15*Missions!$E$6:$E$26*Missions!$J$6:$J$26)+SUMPRODUCT((Missions!$F$6:$F$26="Discount")*(Missions!$A$6:$A$26="Diamond")*'Affiliate Projection'!F16*Missions!$E$6:$E$26*Missions!$J$6:$J$26) -> 215.4 | G9: =SUMPRODUCT((Missions!$F$6:$F$26="Discount")*(Missions!$A$6:$A$26="Bronze")*'Affiliate Projection'!G12*Missions!$E$6:$E$26*Missions!$J$6:$J$26)+SUMPRODUCT((Missions!$F$6:$F$26="Discount")*(Missions!$A$6:$A$26="Silver")*'Affiliate Projection'!G13*Missions!$E$6:$E$26*Missions!$J$6:$J$26)+SUMPRODUCT((Missions!$F$6:$F$26="Discount")*(Missions!$A$6:$A$26="Gold")*'Affiliate Projection'!G14*Missions!$E$6:$E$26*Missions!$J$6:$J$26)+SUMPRODUCT((Missions!$F$6:$F$26="Discount")*(Missions!$A$6:$A$26="Platinum")*'Affiliate Projection'!G15*Missions!$E$6:$E$26*Missions!$J$6:$J$26)+SUMPRODUCT((Missions!$F$6:$F$26="Discount")*(Missions!$A$6:$A$26="Diamond")*'Affiliate Projection'!G16*Missions!$E$6:$E$26*Missions!$J$6:$J$26) -> 248.25 | H9: =SUMPRODUCT((Missions!$F$6:$F$26="Discount")*(Missions!$A$6:$A$26="Bronze")*'Affiliate Projection'!H12*Missions!$E$6:$E$26*Missions!$J$6:$J$26)+SUMPRODUCT((Missions!$F$6:$F$26="Discount")*(Missions!$A$6:$A$26="Silver")*'Affiliate Projection'!H13*Missions!$E$6:$E$26*Missions!$J$6:$J$26)+SUMPRODUCT((Missions!$F$6:$F$26="Discount")*(Missions!$A$6:$A$26="Gold")*'Affiliate Projection'!H14*Missions!$E$6:$E$26*Missions!$J$6:$J$26)+SUMPRODUCT((Missions!$F$6:$F$26="Discount")*(Missions!$A$6:$A$26="Platinum")*'Affiliate Projection'!H15*Missions!$E$6:$E$26*Missions!$J$6:$J$26)+SUMPRODUCT((Missions!$F$6:$F$26="Discount")*(Missions!$A$6:$A$26="Diamond")*'Affiliate Projection'!H16*Missions!$E$6:$E$26*Missions!$J$6:$J$26) -> 277.35 | I9: =SUMPRODUCT((Missions!$F$6:$F$26="Discount")*(Missions!$A$6:$A$26="Bronze")*'Affiliate Projection'!I12*Missions!$E$6:$E$26*Missions!$J$6:$J$26)+SUMPRODUCT((Missions!$F$6:$F$26="Discount")*(Missions!$A$6:$A$26="Silver")*'Affiliate Projection'!I13*Missions!$E$6:$E$26*Missions!$J$6:$J$26)+SUMPRODUCT((Missions!$F$6:$F$26="Discount")*(Missions!$A$6:$A$26="Gold")*'Affiliate Projection'!I14*Missions!$E$6:$E$26*Missions!$J$6:$J$26)+SUMPRODUCT((Missions!$F$6:$F$26="Discount")*(Missions!$A$6:$A$26="Platinum")*'Affiliate Projection'!I15*Missions!$E$6:$E$26*Missions!$J$6:$J$26)+SUMPRODUCT((Missions!$F$6:$F$26="Discount")*(Missions!$A$6:$A$26="Diamond")*'Affiliate Projection'!I16*Missions!$E$6:$E$26*Missions!$J$6:$J$26) -> 307.56 | ... M9: =SUMPRODUCT((Missions!$F$6:$F$26="Discount")*(Missions!$A$6:$A$26="Bronze")*'Affiliate Projection'!M12*Missions!$E$6:$E$26*Missions!$J$6:$J$26)+SUMPRODUCT((Missions!$F$6:$F$26="Discount")*(Missions!$A$6:$A$26="Silver")*'Affiliate Projection'!M13*Missions!$E$6:$E$26*Missions!$J$6:$J$26)+SUMPRODUCT((Missions!$F$6:$F$26="Discount")*(Missions!$A$6:$A$26="Gold")*'Affiliate Projection'!M14*Missions!$E$6:$E$26*Missions!$J$6:$J$26)+SUMPRODUCT((Missions!$F$6:$F$26="Discount")*(Missions!$A$6:$A$26="Platinum")*'Affiliate Projection'!M15*Missions!$E$6:$E$26*Missions!$J$6:$J$26)+SUMPRODUCT((Missions!$F$6:$F$26="Discount")*(Missions!$A$6:$A$26="Diamond")*'Affiliate Projection'!M16*Missions!$E$6:$E$26*Missions!$J$6:$J$26) -> 415.14
A10: Total CM1 Costs | B10: =SUM(B5:B9) -> 10597.285 | C10: =SUM(C5:C9) -> 27744.529 | D10: =SUM(D5:D9) -> 29826.817 | E10: =SUM(E5:E9) -> 35242.398 | F10: =SUM(F5:F9) -> 41052.267 | G10: =SUM(G5:G9) -> 46049.693 | H10: =SUM(H5:H9) -> 50580.169 | I10: =SUM(I5:I9) -> 55283.659 | ... M10: =SUM(M5:M9) -> 71811.428
A12: --- LOYALTY PROGRAM COSTS ---
A13: Gift Card Cost (Welcome) | B13: ='Reward Triggers'!B6*'VIP Levels'!$B$23 -> 0 | C13: ='Reward Triggers'!C6*'VIP Levels'!$B$23 -> 2625 | D13: ='Reward Triggers'!D6*'VIP Levels'!$B$23 -> 1015 | E13: ='Reward Triggers'!E6*'VIP Levels'!$B$23 -> 910 | F13: ='Reward Triggers'!F6*'VIP Levels'!$B$23 -> 910 | G13: ='Reward Triggers'!G6*'VIP Levels'!$B$23 -> 840 | H13: ='Reward Triggers'!H6*'VIP Levels'!$B$23 -> 805 | I13: ='Reward Triggers'!I6*'VIP Levels'!$B$23 -> 770 | ... M13: ='Reward Triggers'!M6*'VIP Levels'!$B$23 -> 630
